Workbook

Sheet Sales Analysis
A1: Mobility Sales Analysis (all figures USD, after discounts)
A2: Summary tables are SUMIFS/COUNTIFS formulas over Clean Data, so they recalculate. No refund or expense data exists in the source, so Total Sales = Units x USD price x (1 - discount).
A4: 1. Sales by region
A5: Country | B5: Continent | C5: Units Sold | D5: Total Sales (USD) | E5: Share of Sales | F5: Rank
A6: India | B6: =INDEX(Lookups!$C$3:$C$6,MATCH(A6,Lookups!$B$3:$B$6,0)) -> Asia | C6: =SUMIFS('Clean Data'!$N$2:$N$145,'Clean Data'!$I$2:$I$145,A6) -> 11350 | D6: =SUMIFS('Clean Data'!$P$2:$P$145,'Clean Data'!$I$2:$I$145,A6) -> 3274230 | E6: =D6/D$10 -> 0.082029982 | F6: =RANK(D6,D$6:D$9) -> 4
A7: China | B7: =INDEX(Lookups!$C$3:$C$6,MATCH(A7,Lookups!$B$3:$B$6,0)) -> Asia | C7: =SUMIFS('Clean Data'!$N$2:$N$145,'Clean Data'!$I$2:$I$145,A7) -> 37450 | D7: =SUMIFS('Clean Data'!$P$2:$P$145,'Clean Data'!$I$2:$I$145,A7) -> 20302030 | E7: =D7/D$10 -> 0.50863108 | F7: =RANK(D7,D$6:D$9) -> 1
A8: France | B8: =INDEX(Lookups!$C$3:$C$6,MATCH(A8,Lookups!$B$3:$B$6,0)) -> Europe | C8: =SUMIFS('Clean Data'!$N$2:$N$145,'Clean Data'!$I$2:$I$145,A8) -> 8450 | D8: =SUMIFS('Clean Data'!$P$2:$P$145,'Clean Data'!$I$2:$I$145,A8) -> 8704557 | E8: =D8/D$10 -> 0.21807712 | F8: =RANK(D8,D$6:D$9) -> 2
A9: Germany | B9: =INDEX(Lookups!$C$3:$C$6,MATCH(A9,Lookups!$B$3:$B$6,0)) -> Europe | C9: =SUMIFS('Clean Data'!$N$2:$N$145,'Clean Data'!$I$2:$I$145,A9) -> 8230 | D9: =SUMIFS('Clean Data'!$P$2:$P$145,'Clean Data'!$I$2:$I$145,A9) -> 7634223 | E9: =D9/D$10 -> 0.19126182 | F9: =RANK(D9,D$6:D$9) -> 3
A10: Total | C10: =SUM(C6:C9) -> 65480 | D10: =SUM(D6:D9) -> 39915040 | E10: =SUM(E6:E9) -> 1
A12: By continent
A13: Continent | C13: Units Sold | D13: Total Sales (USD) | E13: Share of Sales
A14: Asia | C14: =SUMIFS('Clean Data'!$N$2:$N$145,'Clean Data'!$J$2:$J$145,A14) -> 48800 | D14: =SUMIFS('Clean Data'!$P$2:$P$145,'Clean Data'!$J$2:$J$145,A14) -> 23576260 | E14: =D14/D10 -> 0.59066106
A15: Europe | C15: =SUMIFS('Clean Data'!$N$2:$N$145,'Clean Data'!$J$2:$J$145,A15) -> 16680 | D15: =SUMIFS('Clean Data'!$P$2:$P$145,'Clean Data'!$J$2:$J$145,A15) -> 16338780 | E15: =D15/D10 -> 0.40933894
A17: 2. Monthly sales trend
A18: Month | B18: Quarter | C18: Units Sold | D18: Total Sales (USD) | E18: MoM Change
A19: January | B19: ="Q"&ROUNDUP(1/3,0) -> Q1 | C19: =SUMIFS('Clean Data'!$N$2:$N$145,'Clean Data'!$C$2:$C$145,A19) -> 3950 | D19: =SUMIFS('Clean Data'!$P$2:$P$145,'Clean Data'!$C$2:$C$145,A19) -> 2276478
A20: February | B20: ="Q"&ROUNDUP(2/3,0) -> Q1 | C20: =SUMIFS('Clean Data'!$N$2:$N$145,'Clean Data'!$C$2:$C$145,A20) -> 4410 | D20: =SUMIFS('Clean Data'!$P$2:$P$145,'Clean Data'!$C$2:$C$145,A20) -> 2798320 | E20: =D20/D19-1 -> 0.22923217
A21: March | B21: ="Q"&ROUNDUP(3/3,0) -> Q1 | C21: =SUMIFS('Clean Data'!$N$2:$N$145,'Clean Data'!$C$2:$C$145,A21) -> 4410 | D21: =SUMIFS('Clean Data'!$P$2:$P$145,'Clean Data'!$C$2:$C$145,A21) -> 2798320 | E21: =D21/D20-1 -> 0
A22: April | B22: ="Q"&ROUNDUP(4/3,0) -> Q2 | C22: =SUMIFS('Clean Data'!$N$2:$N$145,'Clean Data'!$C$2:$C$145,A22) -> 5550 | D22: =SUMIFS('Clean Data'!$P$2:$P$145,'Clean Data'!$C$2:$C$145,A22) -> 3474980 | E22: =D22/D21-1 -> 0.24180937
A23: May | B23: ="Q"&ROUNDUP(5/3,0) -> Q2 | C23: =SUMIFS('Clean Data'!$N$2:$N$145,'Clean Data'!$C$2:$C$145,A23) -> 5740 | D23: =SUMIFS('Clean Data'!$P$2:$P$145,'Clean Data'!$C$2:$C$145,A23) -> 3633440 | E23: =D23/D22-1 -> 0.045600262
A24: June | B24: ="Q"&ROUNDUP(6/3,0) -> Q2 | C24: =SUMIFS('Clean Data'!$N$2:$N$145,'Clean Data'!$C$2:$C$145,A24) -> 6650 | D24: =SUMIFS('Clean Data'!$P$2:$P$145,'Clean Data'!$C$2:$C$145,A24) -> 4175700 | E24: =D24/D23-1 -> 0.14924149
A25: July | B25: ="Q"&ROUNDUP(7/3,0) -> Q3 | C25: =SUMIFS('Clean Data'!$N$2:$N$145,'Clean Data'!$C$2:$C$145,A25) -> 6530 | D25: =SUMIFS('Clean Data'!$P$2:$P$145,'Clean Data'!$C$2:$C$145,A25) -> 4109420 | E25: =D25/D24-1 -> -0.015872788
A26: August | B26: ="Q"&ROUNDUP(8/3,0) -> Q3 | C26: =SUMIFS('Clean Data'!$N$2:$N$145,'Clean Data'!$C$2:$C$145,A26) -> 5730 | D26: =SUMIFS('Clean Data'!$P$2:$P$145,'Clean Data'!$C$2:$C$145,A26) -> 3630200 | E26: =D26/D25-1 -> -0.116615
A27: September | B27: ="Q"&ROUNDUP(9/3,0) -> Q3 | C27: =SUMIFS('Clean Data'!$N$2:$N$145,'Clean Data'!$C$2:$C$145,A27) -> 5290 | D27: =SUMIFS('Clean Data'!$P$2:$P$145,'Clean Data'!$C$2:$C$145,A27) -> 3390740 | E27: =D27/D26-1 -> -0.065963308
A28: October | B28: ="Q"&ROUNDUP(10/3,0) -> Q4 | C28: =SUMIFS('Clean Data'!$N$2:$N$145,'Clean Data'!$C$2:$C$145,A28) -> 4780 | D28: =SUMIFS('Clean Data'!$P$2:$P$145,'Clean Data'!$C$2:$C$145,A28) -> 3089540 | E28: =D28/D27-1 -> -0.088830167
A29: November | B29: ="Q"&ROUNDUP(11/3,0) -> Q4 | C29: =SUMIFS('Clean Data'!$N$2:$N$145,'Clean Data'!$C$2:$C$145,A29) -> 5300 | D29: =SUMIFS('Clean Data'!$P$2:$P$145,'Clean Data'!$C$2:$C$145,A29) -> 2895678 | E29: =D29/D28-1 -> -0.062747852
A30: December | B30: ="Q"&ROUNDUP(12/3,0) -> Q4 | C30: =SUMIFS('Clean Data'!$N$2:$N$145,'Clean Data'!$C$2:$C$145,A30) -> 7140 | D30: =SUMIFS('Clean Data'!$P$2:$P$145,'Clean Data'!$C$2:$C$145,A30) -> 3642224 | E30: =D30/D29-1 -> 0.25781389
A31: Total | C31: =SUM(C19:C30) -> 65480 | D31: =SUM(D19:D30) -> 39915040
A33: 3. Quarterly performance
A34: Quarter | C34: Units Sold | D34: Total Sales (USD) | E34: QoQ Change | F34: Share of Sales
A35: Q1 | C35: =SUMIFS('Clean Data'!$N$2:$N$145,'Clean Data'!$D$2:$D$145,A35) -> 12770 | D35: =SUMIFS('Clean Data'!$P$2:$P$145,'Clean Data'!$D$2:$D$145,A35) -> 7873118 | F35: =D35/D$39 -> 0.1972469
A36: Q2 | C36: =SUMIFS('Clean Data'!$N$2:$N$145,'Clean Data'!$D$2:$D$145,A36) -> 17940 | D36: =SUMIFS('Clean Data'!$P$2:$P$145,'Clean Data'!$D$2:$D$145,A36) -> 11284120 | E36: =D36/D35-1 -> 0.43324665 | F36: =D36/D$39 -> 0.28270346
A37: Q3 | C37: =SUMIFS('Clean Data'!$N$2:$N$145,'Clean Data'!$D$2:$D$145,A37) -> 17550 | D37: =SUMIFS('Clean Data'!$P$2:$P$145,'Clean Data'!$D$2:$D$145,A37) -> 11130360 | E37: =D37/D36-1 -> -0.013626229 | F37: =D37/D$39 -> 0.27885128
A38: Q4 | C38: =SUMIFS('Clean Data'!$N$2:$N$145,'Clean Data'!$D$2:$D$145,A38) -> 17220 | D38: =SUMIFS('Clean Data'!$P$2:$P$145,'Clean Data'!$D$2:$D$145,A38) -> 9627442 | E38: =D38/D37-1 -> -0.1350287 | F38: =D38/D$39 -> 0.24119836
A39: Total | C39: =SUM(C35:C38) -> 65480 | D39: =SUM(D35:D38) -> 39915040 | F39: =SUM(F35:F38) -> 1
A41: 4. Top product types
A42: Product Type | C42: Units Sold | D42: Total Sales (USD) | E42: Share of Sales | F42: Rank
A43: Electric Unicycle | C43: =SUMIFS('Clean Data'!$N$2:$N$145,'Clean Data'!$E$2:$E$145,A43) -> 13780 | D43: =SUMIFS('Clean Data'!$P$2:$P$145,'Clean Data'!$E$2:$E$145,A43) -> 9994124 | E43: =D43/D$46 -> 0.25038492 | F43: =RANK(D43,D$43:D$45) -> 3
A44: Electric Scooter | C44: =SUMIFS('Clean Data'!$N$2:$N$145,'Clean Data'!$E$2:$E$145,A44) -> 30610 | D44: =SUMIFS('Clean Data'!$P$2:$P$145,'Clean Data'!$E$2:$E$145,A44) -> 16384850 | E44: =D44/D$46 -> 0.41049314 | F44: =RANK(D44,D$43:D$45) -> 1
A45: Electric Skateboard | C45: =SUMIFS('Clean Data'!$N$2:$N$145,'Clean Data'!$E$2:$E$145,A45) -> 21090 | D45: =SUMIFS('Clean Data'!$P$2:$P$145,'Clean Data'!$E$2:$E$145,A45) -> 13536066 | E45: =D45/D$46 -> 0.33912195 | F45: =RANK(D45,D$43:D$45) -> 2
...

Sheet Clean Data
A1: Sales Rep ID | B1: Rep Name (Last, First) | C1: Month | D1: Quarter | E1: Product Type | F1: Street | G1: City | H1: Postal Code | I1: Country | J1: Continent | K1: Currency | L1: Unit Price (Local) | M1: Unit Price (USD) | N1: Units Sold | O1: Discount (%) | P1: Total Sales (USD) | Q1: Speed Range (km/h) | R1: Distance (km) | S1: Rep First Name | T1: Rep Last Name | U1: Min Speed (orig) | V1: Speed (orig) | W1: Distance (orig) | X1: Shipping Address (orig) | Y1: Country Code (orig) | Z1: Unit Price (orig) | AA1: Min Speed (mph, filled) | AB1: Top Speed (mph) | AD1: Legend
A2: 1 | B2: =T2&", "&S2 -> Joshi, Sanya | C2: January | D2: ="Q"&ROUNDUP(MATCH(C2,Lookups!$L$3:$L$14,0)/3,0) -> Q1 | E2: Electric Unicycle | F2: 456 Brigade Road | G2: Bengaluru | H2: 560001 | I2: =INDEX(Lookups!$B$3:$B$6,MATCH(Y2,Lookups!$A$3:$A$6,0)) -> India | J2: =INDEX(Lookups!$C$3:$C$6,MATCH(Y2,Lookups!$A$3:$A$6,0)) -> Asia | K2: =INDEX(Lookups!$D$3:$D$6,MATCH(Y2,Lookups!$A$3:$A$6,0)) -> INR | L2: 30000 | M2: =ROUND(L2*INDEX(Lookups!$G$3:$G$5,MATCH(K2,Lookups!$F$3:$F$5,0)),0) -> 360 | N2: 150 | O2: 10 | P2: =ROUND(N2*M2*(1-O2/100),0) -> 48600 | Q2: =ROUND(AA2*Lookups!$O$3,0)&" - "&ROUND(AB2*Lookups!$O$3,0)&" km/h" -> 24 - 48 km/h | R2: =IF(ISNUMBER(SEARCH("meters",W2)),ROUND(VALUE(SUBSTITUTE(LEFT(W2,FIND(" ",W2)-1),",",""))/Lookups!$O$4,0),ROUND(VALUE(LEFT(W2,FIND(" ",W2)-1))*Lookups!$O$3,0)) -> 48 | S2: Sanya | T2: Joshi | U2: 15 mph | V2: 30 mph | W2: 30 miles | X2: 456 Brigade Road, Bengaluru, 560001 | Y2: IN | Z2: ₹30,000 | AA2: =IF(U2="",INDEX(Lookups!$J$3:$J$5,MATCH(E2,Lookups!$I$3:$I$5,0)),VALUE(LEFT(U2,FIND(" ",U2)-1))) -> 15 | AB2: =VALUE(LEFT(V2,FIND(" ",V2)-1)) -> 30 | AD2: Orange speed range = Min Speed was blank; filled with the standard for that product type
A3: 2 | B3: =T3&", "&S3 -> Joshi, Sanya | C3: January | D3: ="Q"&ROUNDUP(MATCH(C3,Lookups!$L$3:$L$14,0)/3,0) -> Q1 | E3: Electric Scooter | F3: 457 Brigade Road | G3: Bengaluru | H3: 560001 | I3: =INDEX(Lookups!$B$3:$B$6,MATCH(Y3,Lookups!$A$3:$A$6,0)) -> India | J3: =INDEX(Lookups!$C$3:$C$6,MATCH(Y3,Lookups!$A$3:$A$6,0)) -> Asia | K3: =INDEX(Lookups!$D$3:$D$6,MATCH(Y3,Lookups!$A$3:$A$6,0)) -> INR | L3: 25000 | M3: =ROUND(L3*INDEX(Lookups!$G$3:$G$5,MATCH(K3,Lookups!$F$3:$F$5,0)),0) -> 300 | N3: 300 | O3: 10 | P3: =ROUND(N3*M3*(1-O3/100),0) -> 81000 | Q3: =ROUND(AA3*Lookups!$O$3,0)&" - "&ROUND(AB3*Lookups!$O$3,0)&" km/h" -> 32 - 56 km/h | R3: =IF(ISNUMBER(SEARCH("meters",W3)),ROUND(VALUE(SUBSTITUTE(LEFT(W3,FIND(" ",W3)-1),",",""))/Lookups!$O$4,0),ROUND(VALUE(LEFT(W3,FIND(" ",W3)-1))*Lookups!$O$3,0)) -> 64 | S3: Sanya | T3: Joshi | U3: 20 mph | V3: 35 mph | W3: 40 miles | X3: 457 Brigade Road, Bengaluru, 560001 | Y3: IN | Z3: ₹25,000 | AA3: =IF(U3="",INDEX(Lookups!$J$3:$J$5,MATCH(E3,Lookups!$I$3:$I$5,0)),VALUE(LEFT(U3,FIND(" ",U3)-1))) -> 20 | AB3: =VALUE(LEFT(V3,FIND(" ",V3)-1)) -> 35 | AD3: Yellow discount = 15% or more
A4: 3 | B4: =T4&", "&S4 -> Joshi, Sanya | C4: January | D4: ="Q"&ROUNDUP(MATCH(C4,Lookups!$L$3:$L$14,0)/3,0) -> Q1 | E4: Electric Skateboard | F4: 458 Brigade Road | G4: Bengaluru | H4: 560001 | I4: =INDEX(Lookups!$B$3:$B$6,MATCH(Y4,Lookups!$A$3:$A$6,0)) -> India | J4: =INDEX(Lookups!$C$3:$C$6,MATCH(Y4,Lookups!$A$3:$A$6,0)) -> Asia | K4: =INDEX(Lookups!$D$3:$D$6,MATCH(Y4,Lookups!$A$3:$A$6,0)) -> INR | L4: 22000 | M4: =ROUND(L4*INDEX(Lookups!$G$3:$G$5,MATCH(K4,Lookups!$F$3:$F$5,0)),0) -> 264 | N4: 200 | O4: 10 | P4: =ROUND(N4*M4*(1-O4/100),0) -> 47520 | Q4: =ROUND(AA4*Lookups!$O$3,0)&" - "&ROUND(AB4*Lookups!$O$3,0)&" km/h" -> 29 - 45 km/h | R4: =IF(ISNUMBER(SEARCH("meters",W4)),ROUND(VALUE(SUBSTITUTE(LEFT(W4,FIND(" ",W4)-1),",",""))/Lookups!$O$4,0),ROUND(VALUE(LEFT(W4,FIND(" ",W4)-1))*Lookups!$O$3,0)) -> 40 | S4: Sanya | T4: Joshi | U4: 18 mph | V4: 28 mph | W4: 25 miles | X4: 458 Brigade Road, Bengaluru, 560001 | Y4: IN | Z4: ₹22,000 | AA4: =IF(U4="",INDEX(Lookups!$J$3:$J$5,MATCH(E4,Lookups!$I$3:$I$5,0)),VALUE(LEFT(U4,FIND(" ",U4)-1))) -> 18 | AB4: =VALUE(LEFT(V4,FIND(" ",V4)-1)) -> 28 | AD4: Hidden columns S:AB hold the original fields and conversion helpers (unhide to audit)
A5: 4 | B5: =T5&", "&S5 -> Liu, Fang | C5: January | D5: ="Q"&ROUNDUP(MATCH(C5,Lookups!$L$3:$L$14,0)/3,0) -> Q1 | E5: Electric Unicycle | F5: 99 Nanjing Road | G5: Shanghai | H5: 200001 | I5: =INDEX(Lookups!$B$3:$B$6,MATCH(Y5,Lookups!$A$3:$A$6,0)) -> China | J5: =INDEX(Lookups!$C$3:$C$6,MATCH(Y5,Lookups!$A$3:$A$6,0)) -> Asia | K5: =INDEX(Lookups!$D$3:$D$6,MATCH(Y5,Lookups!$A$3:$A$6,0)) -> CNY | L5: 5000 | M5: =ROUND(L5*INDEX(Lookups!$G$3:$G$5,MATCH(K5,Lookups!$F$3:$F$5,0)),0) -> 700 | N5: 500 | O5: 10 | P5: =ROUND(N5*M5*(1-O5/100),0) -> 315000 | Q5: =ROUND(AA5*Lookups!$O$3,0)&" - "&ROUND(AB5*Lookups!$O$3,0)&" km/h" -> 24 - 48 km/h | R5: =IF(ISNUMBER(SEARCH("meters",W5)),ROUND(VALUE(SUBSTITUTE(LEFT(W5,FIND(" ",W5)-1),",",""))/Lookups!$O$4,0),ROUND(VALUE(LEFT(W5,FIND(" ",W5)-1))*Lookups!$O$3,0)) -> 48 | S5: Fang | T5: Liu | U5: 15 mph | V5: 30 mph | W5: 30 miles | X5: 99 Nanjing Road, Shanghai, 200001 | Y5: CN | Z5: ¥5,000 | AA5: =IF(U5="",INDEX(Lookups!$J$3:$J$5,MATCH(E5,Lookups!$I$3:$I$5,0)),VALUE(LEFT(U5,FIND(" ",U5)-1))) -> 15 | AB5: =VALUE(LEFT(V5,FIND(" ",V5)-1)) -> 30
A6: 5 | B6: =T6&", "&S6 -> Liu, Fang | C6: January | D6: ="Q"&ROUNDUP(MATCH(C6,Lookups!$L$3:$L$14,0)/3,0) -> Q1 | E6: Electric Scooter | F6: 100 Nanjing Road | G6: Shanghai | H6: 200001 | I6: =INDEX(Lookups!$B$3:$B$6,MATCH(Y6,Lookups!$A$3:$A$6,0)) -> China | J6: =INDEX(Lookups!$C$3:$C$6,MATCH(Y6,Lookups!$A$3:$A$6,0)) -> Asia | K6: =INDEX(Lookups!$D$3:$D$6,MATCH(Y6,Lookups!$A$3:$A$6,0)) -> CNY | L6: 3500 | M6: =ROUND(L6*INDEX(Lookups!$G$3:$G$5,MATCH(K6,Lookups!$F$3:$F$5,0)),0) -> 490 | N6: 1000 | O6: 10 | P6: =ROUND(N6*M6*(1-O6/100),0) -> 441000 | Q6: =ROUND(AA6*Lookups!$O$3,0)&" - "&ROUND(AB6*Lookups!$O$3,0)&" km/h" -> 32 - 56 km/h | R6: =IF(ISNUMBER(SEARCH("meters",W6)),ROUND(VALUE(SUBSTITUTE(LEFT(W6,FIND(" ",W6)-1),",",""))/Lookups!$O$4,0),ROUND(VALUE(LEFT(W6,FIND(" ",W6)-1))*Lookups!$O$3,0)) -> 64 | S6: Fang | T6: Liu | U6: 20 mph | V6: 35 mph | W6: 40 miles | X6: 100 Nanjing Road, Shanghai, 200001 | Y6: CN | Z6: ¥3,500 | AA6: =IF(U6="",INDEX(Lookups!$J$3:$J$5,MATCH(E6,Lookups!$I$3:$I$5,0)),VALUE(LEFT(U6,FIND(" ",U6)-1))) -> 20 | AB6: =VALUE(LEFT(V6,FIND(" ",V6)-1)) -> 35
A7: 6 | B7: =T7&", "&S7 -> Liu, Fang | C7: January | D7: ="Q"&ROUNDUP(MATCH(C7,Lookups!$L$3:$L$14,0)/3,0) -> Q1 | E7: Electric Skateboard | F7: 101 Nanjing Road | G7: Shanghai | H7: 200001 | I7: =INDEX(Lookups!$B$3:$B$6,MATCH(Y7,Lookups!$A$3:$A$6,0)) -> China | J7: =INDEX(Lookups!$C$3:$C$6,MATCH(Y7,Lookups!$A$3:$A$6,0)) -> Asia | K7: =INDEX(Lookups!$D$3:$D$6,MATCH(Y7,Lookups!$A$3:$A$6,0)) -> CNY | L7: 4200 | M7: =ROUND(L7*INDEX(Lookups!$G$3:$G$5,MATCH(K7,Lookups!$F$3:$F$5,0)),0) -> 588 | N7: 800 | O7: 10 | P7: =ROUND(N7*M7*(1-O7/100),0) -> 423360 | Q7: =ROUND(AA7*Lookups!$O$3,0)&" - "&ROUND(AB7*Lookups!$O$3,0)&" km/h" -> 29 - 45 km/h | R7: =IF(ISNUMBER(SEARCH("meters",W7)),ROUND(VALUE(SUBSTITUTE(LEFT(W7,FIND(" ",W7)-1),",",""))/Lookups!$O$4,0),ROUND(VALUE(LEFT(W7,FIND(" ",W7)-1))*Lookups!$O$3,0)) -> 40 | S7: Fang | T7: Liu | V7: 28 mph | W7: 40,230 meters | X7: 101 Nanjing Road, Shanghai, 200001 | Y7: CN | Z7: ¥4,200 | AA7: =IF(U7="",INDEX(Lookups!$J$3:$J$5,MATCH(E7,Lookups!$I$3:$I$5,0)),VALUE(LEFT(U7,FIND(" ",U7)-1))) -> 18 | AB7: =VALUE(LEFT(V7,FIND(" ",V7)-1)) -> 28
A8: 7 | B8: =T8&", "&S8 -> Fischer, Jonas | C8: January | D8: ="Q"&ROUNDUP(MATCH(C8,Lookups!$L$3:$L$14,0)/3,0) -> Q1 | E8: Electric Unicycle | F8: 303 Ringstraße | G8: Hamburg | H8: 20095 | I8: =INDEX(Lookups!$B$3:$B$6,MATCH(Y8,Lookups!$A$3:$A$6,0)) -> Germany | J8: =INDEX(Lookups!$C$3:$C$6,MATCH(Y8,Lookups!$A$3:$A$6,0)) -> Europe | K8: =INDEX(Lookups!$D$3:$D$6,MATCH(Y8,Lookups!$A$3:$A$6,0)) -> EUR | L8: 1000 | M8: =ROUND(L8*INDEX(Lookups!$G$3:$G$5,MATCH(K8,Lookups!$F$3:$F$5,0)),0) -> 1080 | N8: 120 | O8: 10 | P8: =ROUND(N8*M8*(1-O8/100),0) -> 116640 | Q8: =ROUND(AA8*Lookups!$O$3,0)&" - "&ROUND(AB8*Lookups!$O$3,0)&" km/h" -> 24 - 48 km/h | R8: =IF(ISNUMBER(SEARCH("meters",W8)),ROUND(VALUE(SUBSTITUTE(LEFT(W8,FIND(" ",W8)-1),",",""))/Lookups!$O$4,0),ROUND(VALUE(LEFT(W8,FIND(" ",W8)-1))*Lookups!$O$3,0)) -> 48 | S8: Jonas | T8: Fischer | U8: 15 mph | V8: 30 mph | W8: 48,280 meters | X8: 303 Ringstraße, Hamburg, 20095 | Y8: DE | Z8: €1000 | AA8: =IF(U8="",INDEX(Lookups!$J$3:$J$5,MATCH(E8,Lookups!$I$3:$I$5,0)),VALUE(LEFT(U8,FIND(" ",U8)-1))) -> 15 | AB8: =VALUE(LEFT(V8,FIND(" ",V8)-1)) -> 30
A9: 8 | B9: =T9&", "&S9 -> Fischer, Jonas | C9: January | D9: ="Q"&ROUNDUP(MATCH(C9,Lookups!$L$3:$L$14,0)/3,0) -> Q1 | E9: Electric Scooter | F9: 304 Ringstraße | G9: Hamburg | H9: 20095 | I9: =INDEX(Lookups!$B$3:$B$6,MATCH(Y9,Lookups!$A$3:$A$6,0)) -> Germany | J9: =INDEX(Lookups!$C$3:$C$6,MATCH(Y9,Lookups!$A$3:$A$6,0)) -> Europe | K9: =INDEX(Lookups!$D$3:$D$6,MATCH(Y9,Lookups!$A$3:$A$6,0)) -> EUR | L9: 800 | M9: =ROUND(L9*INDEX(Lookups!$G$3:$G$5,MATCH(K9,Lookups!$F$3:$F$5,0)),0) -> 864 | N9: 200 | O9: 10 | P9: =ROUND(N9*M9*(1-O9/100),0) -> 155520 | Q9: =ROUND(AA9*Lookups!$O$3,0)&" - "&ROUND(AB9*Lookups!$O$3,0)&" km/h" -> 32 - 56 km/h | R9: =IF(ISNUMBER(SEARCH("meters",W9)),ROUND(VALUE(SUBSTITUTE(LEFT(W9,FIND(" ",W9)-1),",",""))/Lookups!$O$4,0),ROUND(VALUE(LEFT(W9,FIND(" ",W9)-1))*Lookups!$O$3,0)) -> 64 | S9: Jonas | T9: Fischer | U9: 20 mph | V9: 35 mph | W9: 40 miles | X9: 304 Ringstraße, Hamburg, 20095 | Y9: DE | Z9: €800 | AA9: =IF(U9="",INDEX(Lookups!$J$3:$J$5,MATCH(E9,Lookups!$I$3:$I$5,0)),VALUE(LEFT(U9,FIND(" ",U9)-1))) -> 20 | AB9: =VALUE(LEFT(V9,FIND(" ",V9)-1)) -> 35
A10: 9 | B10: =T10&", "&S10 -> Fischer, Jonas | C10: January | D10: ="Q"&ROUNDUP(MATCH(C10,Lookups!$L$3:$L$14,0)/3,0) -> Q1 | E10: Electric Skateboard | F10: 305 Ringstraße | G10: Hamburg | H10: 20095 | I10: =INDEX(Lookups!$B$3:$B$6,MATCH(Y10,Lookups!$A$3:$A$6,0)) -> Germany | J10: =INDEX(Lookups!$C$3:$C$6,MATCH(Y10,Lookups!$A$3:$A$6,0)) -> Europe | K10: =INDEX(Lookups!$D$3:$D$6,MATCH(Y10,Lookups!$A$3:$A$6,0)) -> EUR | L10: 950 | M10: =ROUND(L10*INDEX(Lookups!$G$3:$G$5,MATCH(K10,Lookups!$F$3:$F$5,0)),0) -> 1026 | N10: 150 | O10: 10 | P10: =ROUND(N10*M10*(1-O10/100),0) -> 138510 | Q10: =ROUND(AA10*Lookups!$O$3,0)&" - "&ROUND(AB10*Lookups!$O$3,0)&" km/h" -> 29 - 45 km/h | R10: =IF(ISNUMBER(SEARCH("meters",W10)),ROUND(VALUE(SUBSTITUTE(LEFT(W10,FIND(" ",W10)-1),",",""))/Lookups!$O$4,0),ROUND(VALUE(LEFT(W10,FIND(" ",W10)-1))*Lookups!$O$3,0)) -> 40 | S10: Jonas | T10: Fischer | U10: 18 mph | V10: 28 mph | W10: 25 miles | X10: 305 Ringstraße, Hamburg, 20095 | Y10: DE | Z10: €950 | AA10: =IF(U10="",INDEX(Lookups!$J$3:$J$5,MATCH(E10,Lookups!$I$3:$I$5,0)),VALUE(LEFT(U10,FIND(" ",U10)-1))) -> 18 | AB10: =VALUE(LEFT(V10,FIND(" ",V10)-1)) -> 28
A11: 10 | B11: =T11&", "&S11 -> Bernard, Théo | C11: January | D11: ="Q"&ROUNDUP(MATCH(C11,Lookups!$L$3:$L$14,0)/3,0) -> Q1 | E11: Electric Unicycle | F11: 56 Boulevard Saint-Germain | G11: Paris | H11: 75005 | I11: =INDEX(Lookups!$B$3:$B$6,MATCH(Y11,Lookups!$A$3:$A$6,0)) -> France | J11: =INDEX(Lookups!$C$3:$C$6,MATCH(Y11,Lookups!$A$3:$A$6,0)) -> Europe | K11: =INDEX(Lookups!$D$3:$D$6,MATCH(Y11,Lookups!$A$3:$A$6,0)) -> EUR | L11: 1100 | M11: =ROUND(L11*INDEX(Lookups!$G$3:$G$5,MATCH(K11,Lookups!$F$3:$F$5,0)),0) -> 1188 | N11: 100 | O11: 10 | P11: =ROUND(N11*M11*(1-O11/100),0) -> 106920 | Q11: =ROUND(AA11*Lookups!$O$3,0)&" - "&ROUND(AB11*Lookups!$O$3,0)&" km/h" -> 24 - 48 km/h | R11: =IF(ISNUMBER(SEARCH("meters",W11)),ROUND(VALUE(SUBSTITUTE(LEFT(W11,FIND(" ",W11)-1),",",""))/Lookups!$O$4,0),ROUND(VALUE(LEFT(W11,FIND(" ",W11)-1))*Lookups!$O$3,0)) -> 48 | S11: Théo | T11: Bernard | U11: 15 mph | V11: 30 mph | W11: 30 miles | X11: 56 Boulevard Saint-Germain, Paris, 75005 | Y11: FR | Z11: €1100 | AA11: =IF(U11="",INDEX(Lookups!$J$3:$J$5,MATCH(E11,Lookups!$I$3:$I$5,0)),VALUE(LEFT(U11,FIND(" ",U11)-1))) -> 15 | AB11: =VALUE(LEFT(V11,FIND(" ",V11)-1)) -> 30
A12: 11 | B12: =T12&", "&S12 -> Bernard, Théo | C12: January | D12: ="Q"&ROUNDUP(MATCH(C12,Lookups!$L$3:$L$14,0)/3,0) -> Q1 | E12: Electric Scooter | F12: 57 Boulevard Saint-Germain | G12: Paris | H12: 75005 | I12: =INDEX(Lookups!$B$3:$B$6,MATCH(Y12,Lookups!$A$3:$A$6,0)) -> France | J12: =INDEX(Lookups!$C$3:$C$6,MATCH(Y12,Lookups!$A$3:$A$6,0)) -> Europe | K12: =INDEX(Lookups!$D$3:$D$6,MATCH(Y12,Lookups!$A$3:$A$6,0)) -> EUR | L12: 900 | M12: =ROUND(L12*INDEX(Lookups!$G$3:$G$5,MATCH(K12,Lookups!$F$3:$F$5,0)),0) -> 972 | N12: 250 | O12: 10 | P12: =ROUND(N12*M12*(1-O12/100),0) -> 218700 | Q12: =ROUND(AA12*Lookups!$O$3,0)&" - "&ROUND(AB12*Lookups!$O$3,0)&" km/h" -> 32 - 56 km/h | R12: =IF(ISNUMBER(SEARCH("meters",W12)),ROUND(VALUE(SUBSTITUTE(LEFT(W12,FIND(" ",W12)-1),",",""))/Lookups!$O$4,0),ROUND(VALUE(LEFT(W12,FIND(" ",W12)-1))*Lookups!$O$3,0)) -> 64 | S12: Théo | T12: Bernard | U12: 20 mph | V12: 35 mph | W12: 64,370 meters | X12: 57 Boulevard Saint-Germain, Paris, 75005 | Y12: FR | Z12: €900 | AA12: =IF(U12="",INDEX(Lookups!$J$3:$J$5,MATCH(E12,Lookups!$I$3:$I$5,0)),VALUE(LEFT(U12,FIND(" ",U12)-1))) -> 20 | AB12: =VALUE(LEFT(V12,FIND(" ",V12)-1)) -> 35
A13: 12 | B13: =T13&", "&S13 -> Bernard, Théo | C13: January | D13: ="Q"&ROUNDUP(MATCH(C13,Lookups!$L$3:$L$14,0)/3,0) -> Q1 | E13: Electric Skateboard | F13: 58 Boulevard Saint-Germain | G13: Paris | H13: 75005 | I13: =INDEX(Lookups!$B$3:$B$6,MATCH(Y13,Lookups!$A$3:$A$6,0)) -> France | J13: =INDEX(Lookups!$C$3:$C$6,MATCH(Y13,Lookups!$A$3:$A$6,0)) -> Europe | K13: =INDEX(Lookups!$D$3:$D$6,MATCH(Y13,Lookups!$A$3:$A$6,0)) -> EUR | L13: 1050 | M13: =ROUND(L13*INDEX(Lookups!$G$3:$G$5,MATCH(K13,Lookups!$F$3:$F$5,0)),0) -> 1134 | N13: 180 | O13: 10 | P13: =ROUND(N13*M13*(1-O13/100),0) -> 183708 | Q13: =ROUND(AA13*Lookups!$O$3,0)&" - "&ROUND(AB13*Lookups!$O$3,0)&" km/h" -> 29 - 45 km/h | R13: =IF(ISNUMBER(SEARCH("meters",W13)),ROUND(VALUE(SUBSTITUTE(LEFT(W13,FIND(" ",W13)-1),",",""))/Lookups!$O$4,0),ROUND(VALUE(LEFT(W13,FIND(" ",W13)-1))*Lookups!$O$3,0)) -> 40 | S13: Théo | T13: Bernard | U13: 18 mph | V13: 28 mph | W13: 25 miles | X13: 58 Boulevard Saint-Germain, Paris, 75005 | Y13: FR | Z13: €1050 | AA13: =IF(U13="",INDEX(Lookups!$J$3:$J$5,MATCH(E13,Lookups!$I$3:$I$5,0)),VALUE(LEFT(U13,FIND(" ",U13)-1))) -> 18 | AB13: =VALUE(LEFT(V13,FIND(" ",V13)-1)) -> 28
A14: 13 | B14: =T14&", "&S14 -> Joshi, Sanya | C14: February | D14: ="Q"&ROUNDUP(MATCH(C14,Lookups!$L$3:$L$14,0)/3,0) -> Q1 | E14: Electric Unicycle | F14: 456 Brigade Road | G14: Bengaluru | H14: 560001 | I14: =INDEX(Lookups!$B$3:$B$6,MATCH(Y14,Lookups!$A$3:$A$6,0)) -> India | J14: =INDEX(Lookups!$C$3:$C$6,MATCH(Y14,Lookups!$A$3:$A$6,0)) -> Asia | K14: =INDEX(Lookups!$D$3:$D$6,MATCH(Y14,Lookups!$A$3:$A$6,0)) -> INR | L14: 30000 | M14: =ROUND(L14*INDEX(Lookups!$G$3:$G$5,MATCH(K14,Lookups!$F$3:$F$5,0)),0) -> 360 | N14: 160 | O14: 0 | P14: =ROUND(N14*M14*(1-O14/100),0) -> 57600 | Q14: =ROUND(AA14*Lookups!$O$3,0)&" - "&ROUND(AB14*Lookups!$O$3,0)&" km/h" -> 24 - 48 km/h | R14: =IF(ISNUMBER(SEARCH("meters",W14)),ROUND(VALUE(SUBSTITUTE(LEFT(W14,FIND(" ",W14)-1),",",""))/Lookups!$O$4,0),ROUND(VALUE(LEFT(W14,FIND(" ",W14)-1))*Lookups!$O$3,0)) -> 48 | S14: Sanya | T14: Joshi | U14: 15 mph | V14: 30 mph | W14: 30 miles | X14: 456 Brigade Road, Bengaluru, 560001 | Y14: IN | Z14: ₹30,000 | AA14: =IF(U14="",INDEX(Lookups!$J$3:$J$5,MATCH(E14,Lookups!$I$3:$I$5,0)),VALUE(LEFT(U14,FIND(" ",U14)-1))) -> 15 | AB14: =VALUE(LEFT(V14,FIND(" ",V14)-1)) -> 30
A15: 14 | B15: =T15&", "&S15 -> Joshi, Sanya | C15: February | D15: ="Q"&ROUNDUP(MATCH(C15,Lookups!$L$3:$L$14,0)/3,0) -> Q1 | E15: Electric Scooter | F15: 457 Brigade Road | G15: Bengaluru | H15: 560001 | I15: =INDEX(Lookups!$B$3:$B$6,MATCH(Y15,Lookups!$A$3:$A$6,0)) -> India | J15: =INDEX(Lookups!$C$3:$C$6,MATCH(Y15,Lookups!$A$3:$A$6,0)) -> Asia | K15: =INDEX(Lookups!$D$3:$D$6,MATCH(Y15,Lookups!$A$3:$A$6,0)) -> INR | L15: 25000 | M15: =ROUND(L15*INDEX(Lookups!$G$3:$G$5,MATCH(K15,Lookups!$F$3:$F$5,0)),0) -> 300 | N15: 350 | O15: 0 | P15: =ROUND(N15*M15*(1-O15/100),0) -> 105000 | Q15: =ROUND(AA15*Lookups!$O$3,0)&" - "&ROUND(AB15*Lookups!$O$3,0)&" km/h" -> 32 - 56 km/h | R15: =IF(ISNUMBER(SEARCH("meters",W15)),ROUND(VALUE(SUBSTITUTE(LEFT(W15,FIND(" ",W15)-1),",",""))/Lookups!$O$4,0),ROUND(VALUE(LEFT(W15,FIND(" ",W15)-1))*Lookups!$O$3,0)) -> 64 | S15: Sanya | T15: Joshi | V15: 35 mph | W15: 40 miles | X15: 457 Brigade Road, Bengaluru, 560001 | Y15: IN | Z15: ₹25,000 | AA15: =IF(U15="",INDEX(Lookups!$J$3:$J$5,MATCH(E15,Lookups!$I$3:$I$5,0)),VALUE(LEFT(U15,FIND(" ",U15)-1))) -> 20 | AB15: =VALUE(LEFT(V15,FIND(" ",V15)-1)) -> 35
A16: 15 | B16: =T16&", "&S16 -> Joshi, Sanya | C16: February | D16: ="Q"&ROUNDUP(MATCH(C16,Lookups!$L$3:$L$14,0)/3,0) -> Q1 | E16: Electric Skateboard | F16: 458 Brigade Road | G16: Bengaluru | H16: 560001 | I16: =INDEX(Lookups!$B$3:$B$6,MATCH(Y16,Lookups!$A$3:$A$6,0)) -> India | J16: =INDEX(Lookups!$C$3:$C$6,MATCH(Y16,Lookups!$A$3:$A$6,0)) -> Asia | K16: =INDEX(Lookups!$D$3:$D$6,MATCH(Y16,Lookups!$A$3:$A$6,0)) -> INR | L16: 22000 | M16: =ROUND(L16*INDEX(Lookups!$G$3:$G$5,MATCH(K16,Lookups!$F$3:$F$5,0)),0) -> 264 | N16: 220 | O16: 0 | P16: =ROUND(N16*M16*(1-O16/100),0) -> 58080 | Q16: =ROUND(AA16*Lookups!$O$3,0)&" - "&ROUND(AB16*Lookups!$O$3,0)&" km/h" -> 29 - 45 km/h | R16: =IF(ISNUMBER(SEARCH("meters",W16)),ROUND(VALUE(SUBSTITUTE(LEFT(W16,FIND(" ",W16)-1),",",""))/Lookups!$O$4,0),ROUND(VALUE(LEFT(W16,FIND(" ",W16)-1))*Lookups!$O$3,0)) -> 40 | S16: Sanya | T16: Joshi | U16: 18 mph | V16: 28 mph | W16: 25 miles | X16: 458 Brigade Road, Bengaluru, 560001 | Y16: IN | Z16: ₹22,000 | AA16: =IF(U16="",INDEX(Lookups!$J$3:$J$5,MATCH(E16,Lookups!$I$3:$I$5,0)),VALUE(LEFT(U16,FIND(" ",U16)-1))) -> 18 | AB16: =VALUE(LEFT(V16,FIND(" ",V16)-1)) -> 28
A17: 16 | B17: =T17&", "&S17 -> Liu, Fang | C17: February | D17: ="Q"&ROUNDUP(MATCH(C17,Lookups!$L$3:$L$14,0)/3,0) -> Q1 | E17: Electric Unicycle | F17: 99 Nanjing Road | G17: Shanghai | H17: 200001 | I17: =INDEX(Lookups!$B$3:$B$6,MATCH(Y17,Lookups!$A$3:$A$6,0)) -> China | J17: =INDEX(Lookups!$C$3:$C$6,MATCH(Y17,Lookups!$A$3:$A$6,0)) -> Asia | K17: =INDEX(Lookups!$D$3:$D$6,MATCH(Y17,Lookups!$A$3:$A$6,0)) -> CNY | L17: 5000 | M17: =ROUND(L17*INDEX(Lookups!$G$3:$G$5,MATCH(K17,Lookups!$F$3:$F$5,0)),0) -> 700 | N17: 550 | O17: 0 | P17: =ROUND(N17*M17*(1-O17/100),0) -> 385000 | Q17: =ROUND(AA17*Lookups!$O$3,0)&" - "&ROUND(AB17*Lookups!$O$3,0)&" km/h" -> 24 - 48 km/h | R17: =IF(ISNUMBER(SEARCH("meters",W17)),ROUND(VALUE(SUBSTITUTE(LEFT(W17,FIND(" ",W17)-1),",",""))/Lookups!$O$4,0),ROUND(VALUE(LEFT(W17,FIND(" ",W17)-1))*Lookups!$O$3,0)) -> 48 | S17: Fang | T17: Liu | U17: 15 mph | V17: 30 mph | W17: 48,280 meters | X17: 99 Nanjing Road, Shanghai, 200001 | Y17: CN | Z17: ¥5,000 | AA17: =IF(U17="",INDEX(Lookups!$J$3:$J$5,MATCH(E17,Lookups!$I$3:$I$5,0)),VALUE(LEFT(U17,FIND(" ",U17)-1))) -> 15 | AB17: =VALUE(LEFT(V17,FIND(" ",V17)-1)) -> 30
A18: 17 | B18: =T18&", "&S18 -> Liu, Fang | C18: February | D18: ="Q"&ROUNDUP(MATCH(C18,Lookups!$L$3:$L$14,0)/3,0) -> Q1 | E18: Electric Scooter | F18: 100 Nanjing Road | G18: Shanghai | H18: 200001 | I18: =INDEX(Lookups!$B$3:$B$6,MATCH(Y18,Lookups!$A$3:$A$6,0)) -> China | J18: =INDEX(Lookups!$C$3:$C$6,MATCH(Y18,Lookups!$A$3:$A$6,0)) -> Asia | K18: =INDEX(Lookups!$D$3:$D$6,MATCH(Y18,Lookups!$A$3:$A$6,0)) -> CNY | L18: 3500 | M18: =ROUND(L18*INDEX(Lookups!$G$3:$G$5,MATCH(K18,Lookups!$F$3:$F$5,0)),0) -> 490 | N18: 1200 | O18: 0 | P18: =ROUND(N18*M18*(1-O18/100),0) -> 588000 | Q18: =ROUND(AA18*Lookups!$O$3,0)&" - "&ROUND(AB18*Lookups!$O$3,0)&" km/h" -> 32 - 56 km/h | R18: =IF(ISNUMBER(SEARCH("meters",W18)),ROUND(VALUE(SUBSTITUTE(LEFT(W18,FIND(" ",W18)-1),",",""))/Lookups!$O$4,0),ROUND(VALUE(LEFT(W18,FIND(" ",W18)-1))*Lookups!$O$3,0)) -> 64 | S18: Fang | T18: Liu | U18: 20 mph | V18: 35 mph | W18: 40 miles | X18: 100 Nanjing Road, Shanghai, 200001 | Y18: CN | Z18: ¥3,500 | AA18: =IF(U18="",INDEX(Lookups!$J$3:$J$5,MATCH(E18,Lookups!$I$3:$I$5,0)),VALUE(LEFT(U18,FIND(" ",U18)-1))) -> 20 | AB18: =VALUE(LEFT(V18,FIND(" ",V18)-1)) -> 35
A19: 18 | B19: =T19&", "&S19 -> Liu, Fang | C19: February | D19: ="Q"&ROUNDUP(MATCH(C19,Lookups!$L$3:$L$14,0)/3,0) -> Q1 | E19: Electric Skateboard | F19: 101 Nanjing Road | G19: Shanghai | H19: 200001 | I19: =INDEX(Lookups!$B$3:$B$6,MATCH(Y19,Lookups!$A$3:$A$6,0)) -> China | J19: =INDEX(Lookups!$C$3:$C$6,MATCH(Y19,Lookups!$A$3:$A$6,0)) -> Asia | K19: =INDEX(Lookups!$D$3:$D$6,MATCH(Y19,Lookups!$A$3:$A$6,0)) -> CNY | L19: 4200 | M19: =ROUND(L19*INDEX(Lookups!$G$3:$G$5,MATCH(K19,Lookups!$F$3:$F$5,0)),0) -> 588 | N19: 850 | O19: 0 | P19: =ROUND(N19*M19*(1-O19/100),0) -> 499800 | Q19: =ROUND(AA19*Lookups!$O$3,0)&" - "&ROUND(AB19*Lookups!$O$3,0)&" km/h" -> 29 - 45 km/h | R19: =IF(ISNUMBER(SEARCH("meters",W19)),ROUND(VALUE(SUBSTITUTE(LEFT(W19,FIND(" ",W19)-1),",",""))/Lookups!$O$4,0),ROUND(VALUE(LEFT(W19,FIND(" ",W19)-1))*Lookups!$O$3,0)) -> 40 | S19: Fang | T19: Liu | U19: 18 mph | V19: 28 mph | W19: 25 miles | X19: 101 Nanjing Road, Shanghai, 200001 | Y19: CN | Z19: ¥4,200 | AA19: =IF(U19="",INDEX(Lookups!$J$3:$J$5,MATCH(E19,Lookups!$I$3:$I$5,0)),VALUE(LEFT(U19,FIND(" ",U19)-1))) -> 18 | AB19: =VALUE(LEFT(V19,FIND(" ",V19)-1)) -> 28
A20: 19 | B20: =T20&", "&S20 -> Fischer, Jonas | C20: February | D20: ="Q"&ROUNDUP(MATCH(C20,Lookups!$L$3:$L$14,0)/3,0) -> Q1 | E20: Electric Unicycle | F20: 303 Ringstraße | G20: Hamburg | H20: 20095 | I20: =INDEX(Lookups!$B$3:$B$6,MATCH(Y20,Lookups!$A$3:$A$6,0)) -> Germany | J20: =INDEX(Lookups!$C$3:$C$6,MATCH(Y20,Lookups!$A$3:$A$6,0)) -> Europe | K20: =INDEX(Lookups!$D$3:$D$6,MATCH(Y20,Lookups!$A$3:$A$6,0)) -> EUR | L20: 1000 | M20: =ROUND(L20*INDEX(Lookups!$G$3:$G$5,MATCH(K20,Lookups!$F$3:$F$5,0)),0) -> 1080 | N20: 130 | O20: 0 | P20: =ROUND(N20*M20*(1-O20/100),0) -> 140400 | Q20: =ROUND(AA20*Lookups!$O$3,0)&" - "&ROUND(AB20*Lookups!$O$3,0)&" km/h" -> 24 - 48 km/h | R20: =IF(ISNUMBER(SEARCH("meters",W20)),ROUND(VALUE(SUBSTITUTE(LEFT(W20,FIND(" ",W20)-1),",",""))/Lookups!$O$4,0),ROUND(VALUE(LEFT(W20,FIND(" ",W20)-1))*Lookups!$O$3,0)) -> 48 | S20: Jonas | T20: Fischer | U20: 15 mph | V20: 30 mph | W20: 30 miles | X20: 303 Ringstraße, Hamburg, 20095 | Y20: DE | Z20: €1000 | AA20: =IF(U20="",INDEX(Lookups!$J$3:$J$5,MATCH(E20,Lookups!$I$3:$I$5,0)),VALUE(LEFT(U20,FIND(" ",U20)-1))) -> 15 | AB20: =VALUE(LEFT(V20,FIND(" ",V20)-1)) -> 30
A21: 20 | B21: =T21&", "&S21 -> Fischer, Jonas | C21: February | D21: ="Q"&ROUNDUP(MATCH(C21,Lookups!$L$3:$L$14,0)/3,0) -> Q1 | E21: Electric Scooter | F21: 304 Ringstraße | G21: Hamburg | H21: 20095 | I21: =INDEX(Lookups!$B$3:$B$6,MATCH(Y21,Lookups!$A$3:$A$6,0)) -> Germany | J21: =INDEX(Lookups!$C$3:$C$6,MATCH(Y21,Lookups!$A$3:$A$6,0)) -> Europe | K21: =INDEX(Lookups!$D$3:$D$6,MATCH(Y21,Lookups!$A$3:$A$6,0)) -> EUR | L21: 800 | M21: =ROUND(L21*INDEX(Lookups!$G$3:$G$5,MATCH(K21,Lookups!$F$3:$F$5,0)),0) -> 864 | N21: 220 | O21: 0 | P21: =ROUND(N21*M21*(1-O21/100),0) -> 190080 | Q21: =ROUND(AA21*Lookups!$O$3,0)&" - "&ROUND(AB21*Lookups!$O$3,0)&" km/h" -> 32 - 56 km/h | R21: =IF(ISNUMBER(SEARCH("meters",W21)),ROUND(VALUE(SUBSTITUTE(LEFT(W21,FIND(" ",W21)-1),",",""))/Lookups!$O$4,0),ROUND(VALUE(LEFT(W21,FIND(" ",W21)-1))*Lookups!$O$3,0)) -> 64 | S21: Jonas | T21: Fischer | U21: 20 mph | V21: 35 mph | W21: 40 miles | X21: 304 Ringstraße, Hamburg, 20095 | Y21: DE | Z21: €800 | AA21: =IF(U21="",INDEX(Lookups!$J$3:$J$5,MATCH(E21,Lookups!$I$3:$I$5,0)),VALUE(LEFT(U21,FIND(" ",U21)-1))) -> 20 | AB21: =VALUE(LEFT(V21,FIND(" ",V21)-1)) -> 35
A22: 21 | B22: =T22&", "&S22 -> Fischer, Jonas | C22: February | D22: ="Q"&ROUNDUP(MATCH(C22,Lookups!$L$3:$L$14,0)/3,0) -> Q1 | E22: Electric Skateboard | F22: 305 Ringstraße | G22: Hamburg | H22: 20095 | I22: =INDEX(Lookups!$B$3:$B$6,MATCH(Y22,Lookups!$A$3:$A$6,0)) -> Germany | J22: =INDEX(Lookups!$C$3:$C$6,MATCH(Y22,Lookups!$A$3:$A$6,0)) -> Europe | K22: =INDEX(Lookups!$D$3:$D$6,MATCH(Y22,Lookups!$A$3:$A$6,0)) -> EUR | L22: 950 | M22: =ROUND(L22*INDEX(Lookups!$G$3:$G$5,MATCH(K22,Lookups!$F$3:$F$5,0)),0) -> 1026 | N22: 160 | O22: 0 | P22: =ROUND(N22*M22*(1-O22/100),0) -> 164160 | Q22: =ROUND(AA22*Lookups!$O$3,0)&" - "&ROUND(AB22*Lookups!$O$3,0)&" km/h" -> 29 - 45 km/h | R22: =IF(ISNUMBER(SEARCH("meters",W22)),ROUND(VALUE(SUBSTITUTE(LEFT(W22,FIND(" ",W22)-1),",",""))/Lookups!$O$4,0),ROUND(VALUE(LEFT(W22,FIND(" ",W22)-1))*Lookups!$O$3,0)) -> 40 | S22: Jonas | T22: Fischer | U22: 18 mph | V22: 28 mph | W22: 25 miles | X22: 305 Ringstraße, Hamburg, 20095 | Y22: DE | Z22: €950 | AA22: =IF(U22="",INDEX(Lookups!$J$3:$J$5,MATCH(E22,Lookups!$I$3:$I$5,0)),VALUE(LEFT(U22,FIND(" ",U22)-1))) -> 18 | AB22: =VALUE(LEFT(V22,FIND(" ",V22)-1)) -> 28
A23: 22 | B23: =T23&", "&S23 -> Bernard, Théo | C23: February | D23: ="Q"&ROUNDUP(MATCH(C23,Lookups!$L$3:$L$14,0)/3,0) -> Q1 | E23: Electric Unicycle | F23: 56 Boulevard Saint-Germain | G23: Paris | H23: 75005 | I23: =INDEX(Lookups!$B$3:$B$6,MATCH(Y23,Lookups!$A$3:$A$6,0)) -> France | J23: =INDEX(Lookups!$C$3:$C$6,MATCH(Y23,Lookups!$A$3:$A$6,0)) -> Europe | K23: =INDEX(Lookups!$D$3:$D$6,MATCH(Y23,Lookups!$A$3:$A$6,0)) -> EUR | L23: 1100 | M23: =ROUND(L23*INDEX(Lookups!$G$3:$G$5,MATCH(K23,Lookups!$F$3:$F$5,0)),0) -> 1188 | N23: 110 | O23: 0 | P23: =ROUND(N23*M23*(1-O23/100),0) -> 130680 | Q23: =ROUND(AA23*Lookups!$O$3,0)&" - "&ROUND(AB23*Lookups!$O$3,0)&" km/h" -> 24 - 48 km/h | R23: =IF(ISNUMBER(SEARCH("meters",W23)),ROUND(VALUE(SUBSTITUTE(LEFT(W23,FIND(" ",W23)-1),",",""))/Lookups!$O$4,0),ROUND(VALUE(LEFT(W23,FIND(" ",W23)-1))*Lookups!$O$3,0)) -> 48 | S23: Théo | T23: Bernard | U23: 15 mph | V23: 30 mph | W23: 30 miles | X23: 56 Boulevard Saint-Germain, Paris, 75005 | Y23: FR | Z23: €1100 | AA23: =IF(U23="",INDEX(Lookups!$J$3:$J$5,MATCH(E23,Lookups!$I$3:$I$5,0)),VALUE(LEFT(U23,FIND(" ",U23)-1))) -> 15 | AB23: =VALUE(LEFT(V23,FIND(" ",V23)-1)) -> 30
A24: 23 | B24: =T24&", "&S24 -> Bernard, Théo | C24: February | D24: ="Q"&ROUNDUP(MATCH(C24,Lookups!$L$3:$L$14,0)/3,0) -> Q1 | E24: Electric Scooter | F24: 57 Boulevard Saint-Germain | G24: Paris | H24: 75005 | I24: =INDEX(Lookups!$B$3:$B$6,MATCH(Y24,Lookups!$A$3:$A$6,0)) -> France | J24: =INDEX(Lookups!$C$3:$C$6,MATCH(Y24,Lookups!$A$3:$A$6,0)) -> Europe | K24: =INDEX(Lookups!$D$3:$D$6,MATCH(Y24,Lookups!$A$3:$A$6,0)) -> EUR | L24: 900 | M24: =ROUND(L24*INDEX(Lookups!$G$3:$G$5,MATCH(K24,Lookups!$F$3:$F$5,0)),0) -> 972 | N24: 260 | O24: 0 | P24: =ROUND(N24*M24*(1-O24/100),0) -> 252720 | Q24: =ROUND(AA24*Lookups!$O$3,0)&" - "&ROUND(AB24*Lookups!$O$3,0)&" km/h" -> 32 - 56 km/h | R24: =IF(ISNUMBER(SEARCH("meters",W24)),ROUND(VALUE(SUBSTITUTE(LEFT(W24,FIND(" ",W24)-1),",",""))/Lookups!$O$4,0),ROUND(VALUE(LEFT(W24,FIND(" ",W24)-1))*Lookups!$O$3,0)) -> 64 | S24: Théo | T24: Bernard | U24: 20 mph | V24: 35 mph | W24: 40 miles | X24: 57 Boulevard Saint-Germain, Paris, 75005 | Y24: FR | Z24: €900 | AA24: =IF(U24="",INDEX(Lookups!$J$3:$J$5,MATCH(E24,Lookups!$I$3:$I$5,0)),VALUE(LEFT(U24,FIND(" ",U24)-1))) -> 20 | AB24: =VALUE(LEFT(V24,FIND(" ",V24)-1)) -> 35
A25: 24 | B25: =T25&", "&S25 -> Bernard, Théo | C25: February | D25: ="Q"&ROUNDUP(MATCH(C25,Lookups!$L$3:$L$14,0)/3,0) -> Q1 | E25: Electric Skateboard | F25: 58 Boulevard Saint-Germain | G25: Paris | H25: 75005 | I25: =INDEX(Lookups!$B$3:$B$6,MATCH(Y25,Lookups!$A$3:$A$6,0)) -> France | J25: =INDEX(Lookups!$C$3:$C$6,MATCH(Y25,Lookups!$A$3:$A$6,0)) -> Europe | K25: =INDEX(Lookups!$D$3:$D$6,MATCH(Y25,Lookups!$A$3:$A$6,0)) -> EUR | L25: 1050 | M25: =ROUND(L25*INDEX(Lookups!$G$3:$G$5,MATCH(K25,Lookups!$F$3:$F$5,0)),0) -> 1134 | N25: 200 | O25: 0 | P25: =ROUND(N25*M25*(1-O25/100),0) -> 226800 | Q25: =ROUND(AA25*Lookups!$O$3,0)&" - "&ROUND(AB25*Lookups!$O$3,0)&" km/h" -> 29 - 45 km/h | R25: =IF(ISNUMBER(SEARCH("meters",W25)),ROUND(VALUE(SUBSTITUTE(LEFT(W25,FIND(" ",W25)-1),",",""))/Lookups!$O$4,0),ROUND(VALUE(LEFT(W25,FIND(" ",W25)-1))*Lookups!$O$3,0)) -> 40 | S25: Théo | T25: Bernard | U25: 18 mph | V25: 28 mph | W25: 40,230 meters | X25: 58 Boulevard Saint-Germain, Paris, 75005 | Y25: FR | Z25: €1050 | AA25: =IF(U25="",INDEX(Lookups!$J$3:$J$5,MATCH(E25,Lookups!$I$3:$I$5,0)),VALUE(LEFT(U25,FIND(" ",U25)-1))) -> 18 | AB25: =VALUE(LEFT(V25,FIND(" ",V25)-1)) -> 28
A26: 25 | B26: =T26&", "&S26 -> Joshi, Sanya | C26: March | D26: ="Q"&ROUNDUP(MATCH(C26,Lookups!$L$3:$L$14,0)/3,0) -> Q1 | E26: Electric Unicycle | F26: 456 Brigade Road | G26: Bengaluru | H26: 560001 | I26: =INDEX(Lookups!$B$3:$B$6,MATCH(Y26,Lookups!$A$3:$A$6,0)) -> India | J26: =INDEX(Lookups!$C$3:$C$6,MATCH(Y26,Lookups!$A$3:$A$6,0)) -> Asia | K26: =INDEX(Lookups!$D$3:$D$6,MATCH(Y26,Lookups!$A$3:$A$6,0)) -> INR | L26: 30000 | M26: =ROUND(L26*INDEX(Lookups!$G$3:$G$5,MATCH(K26,Lookups!$F$3:$F$5,0)),0) -> 360 | N26: 160 | O26: 0 | P26: =ROUND(N26*M26*(1-O26/100),0) -> 57600 | Q26: =ROUND(AA26*Lookups!$O$3,0)&" - "&ROUND(AB26*Lookups!$O$3,0)&" km/h" -> 24 - 48 km/h | R26: =IF(ISNUMBER(SEARCH("meters",W26)),ROUND(VALUE(SUBSTITUTE(LEFT(W26,FIND(" ",W26)-1),",",""))/Lookups!$O$4,0),ROUND(VALUE(LEFT(W26,FIND(" ",W26)-1))*Lookups!$O$3,0)) -> 48 | S26: Sanya | T26: Joshi | U26: 15 mph | V26: 30 mph | W26: 30 miles | X26: 456 Brigade Road, Bengaluru, 560001 | Y26: IN | Z26: ₹30,000 | AA26: =IF(U26="",INDEX(Lookups!$J$3:$J$5,MATCH(E26,Lookups!$I$3:$I$5,0)),VALUE(LEFT(U26,FIND(" ",U26)-1))) -> 15 | AB26: =VALUE(LEFT(V26,FIND(" ",V26)-1)) -> 30
A27: 26 | B27: =T27&", "&S27 -> Joshi, Sanya | C27: March | D27: ="Q"&ROUNDUP(MATCH(C27,Lookups!$L$3:$L$14,0)/3,0) -> Q1 | E27: Electric Scooter | F27: 457 Brigade Road | G27: Bengaluru | H27: 560001 | I27: =INDEX(Lookups!$B$3:$B$6,MATCH(Y27,Lookups!$A$3:$A$6,0)) -> India | J27: =INDEX(Lookups!$C$3:$C$6,MATCH(Y27,Lookups!$A$3:$A$6,0)) -> Asia | K27: =INDEX(Lookups!$D$3:$D$6,MATCH(Y27,Lookups!$A$3:$A$6,0)) -> INR | L27: 25000 | M27: =ROUND(L27*INDEX(Lookups!$G$3:$G$5,MATCH(K27,Lookups!$F$3:$F$5,0)),0) -> 300 | N27: 350 | O27: 0 | P27: =ROUND(N27*M27*(1-O27/100),0) -> 105000 | Q27: =ROUND(AA27*Lookups!$O$3,0)&" - "&ROUND(AB27*Lookups!$O$3,0)&" km/h" -> 32 - 56 km/h | R27: =IF(ISNUMBER(SEARCH("meters",W27)),ROUND(VALUE(SUBSTITUTE(LEFT(W27,FIND(" ",W27)-1),",",""))/Lookups!$O$4,0),ROUND(VALUE(LEFT(W27,FIND(" ",W27)-1))*Lookups!$O$3,0)) -> 64 | S27: Sanya | T27: Joshi | V27: 35 mph | W27: 40 miles | X27: 457 Brigade Road, Bengaluru, 560001 | Y27: IN | Z27: ₹25,000 | AA27: =IF(U27="",INDEX(Lookups!$J$3:$J$5,MATCH(E27,Lookups!$I$3:$I$5,0)),VALUE(LEFT(U27,FIND(" ",U27)-1))) -> 20 | AB27: =VALUE(LEFT(V27,FIND(" ",V27)-1)) -> 35
A28: 27 | B28: =T28&", "&S28 -> Joshi, Sanya | C28: March | D28: ="Q"&ROUNDUP(MATCH(C28,Lookups!$L$3:$L$14,0)/3,0) -> Q1 | E28: Electric Skateboard | F28: 458 Brigade Road | G28: Bengaluru | H28: 560001 | I28: =INDEX(Lookups!$B$3:$B$6,MATCH(Y28,Lookups!$A$3:$A$6,0)) -> India | J28: =INDEX(Lookups!$C$3:$C$6,MATCH(Y28,Lookups!$A$3:$A$6,0)) -> Asia | K28: =INDEX(Lookups!$D$3:$D$6,MATCH(Y28,Lookups!$A$3:$A$6,0)) -> INR | L28: 22000 | M28: =ROUND(L28*INDEX(Lookups!$G$3:$G$5,MATCH(K28,Lookups!$F$3:$F$5,0)),0) -> 264 | N28: 220 | O28: 0 | P28: =ROUND(N28*M28*(1-O28/100),0) -> 58080 | Q28: =ROUND(AA28*Lookups!$O$3,0)&" - "&ROUND(AB28*Lookups!$O$3,0)&" km/h" -> 29 - 45 km/h | R28: =IF(ISNUMBER(SEARCH("meters",W28)),ROUND(VALUE(SUBSTITUTE(LEFT(W28,FIND(" ",W28)-1),",",""))/Lookups!$O$4,0),ROUND(VALUE(LEFT(W28,FIND(" ",W28)-1))*Lookups!$O$3,0)) -> 40 | S28: Sanya | T28: Joshi | U28: 18 mph | V28: 28 mph | W28: 25 miles | X28: 458 Brigade Road, Bengaluru, 560001 | Y28: IN | Z28: ₹22,000 | AA28: =IF(U28="",INDEX(Lookups!$J$3:$J$5,MATCH(E28,Lookups!$I$3:$I$5,0)),VALUE(LEFT(U28,FIND(" ",U28)-1))) -> 18 | AB28: =VALUE(LEFT(V28,FIND(" ",V28)-1)) -> 28
A29: 28 | B29: =T29&", "&S29 -> Liu, Fang | C29: March | D29: ="Q"&ROUNDUP(MATCH(C29,Lookups!$L$3:$L$14,0)/3,0) -> Q1 | E29: Electric Unicycle | F29: 99 Nanjing Road | G29: Shanghai | H29: 200001 | I29: =INDEX(Lookups!$B$3:$B$6,MATCH(Y29,Lookups!$A$3:$A$6,0)) -> China | J29: =INDEX(Lookups!$C$3:$C$6,MATCH(Y29,Lookups!$A$3:$A$6,0)) -> Asia | K29: =INDEX(Lookups!$D$3:$D$6,MATCH(Y29,Lookups!$A$3:$A$6,0)) -> CNY | L29: 5000 | M29: =ROUND(L29*INDEX(Lookups!$G$3:$G$5,MATCH(K29,Lookups!$F$3:$F$5,0)),0) -> 700 | N29: 550 | O29: 0 | P29: =ROUND(N29*M29*(1-O29/100),0) -> 385000 | Q29: =ROUND(AA29*Lookups!$O$3,0)&" - "&ROUND(AB29*Lookups!$O$3,0)&" km/h" -> 24 - 48 km/h | R29: =IF(ISNUMBER(SEARCH("meters",W29)),ROUND(VALUE(SUBSTITUTE(LEFT(W29,FIND(" ",W29)-1),",",""))/Lookups!$O$4,0),ROUND(VALUE(LEFT(W29,FIND(" ",W29)-1))*Lookups!$O$3,0)) -> 48 | S29: Fang | T29: Liu | U29: 15 mph | V29: 30 mph | W29: 30 miles | X29: 99 Nanjing Road, Shanghai, 200001 | Y29: CN | Z29: ¥5,000 | AA29: =IF(U29="",INDEX(Lookups!$J$3:$J$5,MATCH(E29,Lookups!$I$3:$I$5,0)),VALUE(LEFT(U29,FIND(" ",U29)-1))) -> 15 | AB29: =VALUE(LEFT(V29,FIND(" ",V29)-1)) -> 30
A30: 29 | B30: =T30&", "&S30 -> Liu, Fang | C30: March | D30: ="Q"&ROUNDUP(MATCH(C30,Lookups!$L$3:$L$14,0)/3,0) -> Q1 | E30: Electric Scooter | F30: 100 Nanjing Road | G30: Shanghai | H30: 200001 | I30: =INDEX(Lookups!$B$3:$B$6,MATCH(Y30,Lookups!$A$3:$A$6,0)) -> China | J30: =INDEX(Lookups!$C$3:$C$6,MATCH(Y30,Lookups!$A$3:$A$6,0)) -> Asia | K30: =INDEX(Lookups!$D$3:$D$6,MATCH(Y30,Lookups!$A$3:$A$6,0)) -> CNY | L30: 3500 | M30: =ROUND(L30*INDEX(Lookups!$G$3:$G$5,MATCH(K30,Lookups!$F$3:$F$5,0)),0) -> 490 | N30: 1200 | O30: 0 | P30: =ROUND(N30*M30*(1-O30/100),0) -> 588000 | Q30: =ROUND(AA30*Lookups!$O$3,0)&" - "&ROUND(AB30*Lookups!$O$3,0)&" km/h" -> 32 - 56 km/h | R30: =IF(ISNUMBER(SEARCH("meters",W30)),ROUND(VALUE(SUBSTITUTE(LEFT(W30,FIND(" ",W30)-1),",",""))/Lookups!$O$4,0),ROUND(VALUE(LEFT(W30,FIND(" ",W30)-1))*Lookups!$O$3,0)) -> 64 | S30: Fang | T30: Liu | U30: 20 mph | V30: 35 mph | W30: 64,370 meters | X30: 100 Nanjing Road, Shanghai, 200001 | Y30: CN | Z30: ¥3,500 | AA30: =IF(U30="",INDEX(Lookups!$J$3:$J$5,MATCH(E30,Lookups!$I$3:$I$5,0)),VALUE(LEFT(U30,FIND(" ",U30)-1))) -> 20 | AB30: =VALUE(LEFT(V30,FIND(" ",V30)-1)) -> 35
A31: 30 | B31: =T31&", "&S31 -> Liu, Fang | C31: March | D31: ="Q"&ROUNDUP(MATCH(C31,Lookups!$L$3:$L$14,0)/3,0) -> Q1 | E31: Electric Skateboard | F31: 101 Nanjing Road | G31: Shanghai | H31: 200001 | I31: =INDEX(Lookups!$B$3:$B$6,MATCH(Y31,Lookups!$A$3:$A$6,0)) -> China | J31: =INDEX(Lookups!$C$3:$C$6,MATCH(Y31,Lookups!$A$3:$A$6,0)) -> Asia | K31: =INDEX(Lookups!$D$3:$D$6,MATCH(Y31,Lookups!$A$3:$A$6,0)) -> CNY | L31: 4200 | M31: =ROUND(L31*INDEX(Lookups!$G$3:$G$5,MATCH(K31,Lookups!$F$3:$F$5,0)),0) -> 588 | N31: 850 | O31: 0 | P31: =ROUND(N31*M31*(1-O31/100),0) -> 499800 | Q31: =ROUND(AA31*Lookups!$O$3,0)&" - "&ROUND(AB31*Lookups!$O$3,0)&" km/h" -> 29 - 45 km/h | R31: =IF(ISNUMBER(SEARCH("meters",W31)),ROUND(VALUE(SUBSTITUTE(LEFT(W31,FIND(" ",W31)-1),",",""))/Lookups!$O$4,0),ROUND(VALUE(LEFT(W31,FIND(" ",W31)-1))*Lookups!$O$3,0)) -> 40 | S31: Fang | T31: Liu | U31: 18 mph | V31: 28 mph | W31: 25 miles | X31: 101 Nanjing Road, Shanghai, 200001 | Y31: CN | Z31: ¥4,200 | AA31: =IF(U31="",INDEX(Lookups!$J$3:$J$5,MATCH(E31,Lookups!$I$3:$I$5,0)),VALUE(LEFT(U31,FIND(" ",U31)-1))) -> 18 | AB31: =VALUE(LEFT(V31,FIND(" ",V31)-1)) -> 28
A32: 31 | B32: =T32&", "&S32 -> Fischer, Jonas | C32: March | D32: ="Q"&ROUNDUP(MATCH(C32,Lookups!$L$3:$L$14,0)/3,0) -> Q1 | E32: Electric Unicycle | F32: 303 Ringstraße | G32: Hamburg | H32: 20095 | I32: =INDEX(Lookups!$B$3:$B$6,MATCH(Y32,Lookups!$A$3:$A$6,0)) -> Germany | J32: =INDEX(Lookups!$C$3:$C$6,MATCH(Y32,Lookups!$A$3:$A$6,0)) -> Europe | K32: =INDEX(Lookups!$D$3:$D$6,MATCH(Y32,Lookups!$A$3:$A$6,0)) -> EUR | L32: 1000 | M32: =ROUND(L32*INDEX(Lookups!$G$3:$G$5,MATCH(K32,Lookups!$F$3:$F$5,0)),0) -> 1080 | N32: 130 | O32: 0 | P32: =ROUND(N32*M32*(1-O32/100),0) -> 140400 | Q32: =ROUND(AA32*Lookups!$O$3,0)&" - "&ROUND(AB32*Lookups!$O$3,0)&" km/h" -> 24 - 48 km/h | R32: =IF(ISNUMBER(SEARCH("meters",W32)),ROUND(VALUE(SUBSTITUTE(LEFT(W32,FIND(" ",W32)-1),",",""))/Lookups!$O$4,0),ROUND(VALUE(LEFT(W32,FIND(" ",W32)-1))*Lookups!$O$3,0)) -> 48 | S32: Jonas | T32: Fischer | U32: 15 mph | V32: 30 mph | W32: 30 miles | X32: 303 Ringstraße, Hamburg, 20095 | Y32: DE | Z32: €1000 | AA32: =IF(U32="",INDEX(Lookups!$J$3:$J$5,MATCH(E32,Lookups!$I$3:$I$5,0)),VALUE(LEFT(U32,FIND(" ",U32)-1))) -> 15 | AB32: =VALUE(LEFT(V32,FIND(" ",V32)-1)) -> 30
A33: 32 | B33: =T33&", "&S33 -> Fischer, Jonas | C33: March | D33: ="Q"&ROUNDUP(MATCH(C33,Lookups!$L$3:$L$14,0)/3,0) -> Q1 | E33: Electric Scooter | F33: 304 Ringstraße | G33: Hamburg | H33: 20095 | I33: =INDEX(Lookups!$B$3:$B$6,MATCH(Y33,Lookups!$A$3:$A$6,0)) -> Germany | J33: =INDEX(Lookups!$C$3:$C$6,MATCH(Y33,Lookups!$A$3:$A$6,0)) -> Europe | K33: =INDEX(Lookups!$D$3:$D$6,MATCH(Y33,Lookups!$A$3:$A$6,0)) -> EUR | L33: 800 | M33: =ROUND(L33*INDEX(Lookups!$G$3:$G$5,MATCH(K33,Lookups!$F$3:$F$5,0)),0) -> 864 | N33: 220 | O33: 0 | P33: =ROUND(N33*M33*(1-O33/100),0) -> 190080 | Q33: =ROUND(AA33*Lookups!$O$3,0)&" - "&ROUND(AB33*Lookups!$O$3,0)&" km/h" -> 32 - 56 km/h | R33: =IF(ISNUMBER(SEARCH("meters",W33)),ROUND(VALUE(SUBSTITUTE(LEFT(W33,FIND(" ",W33)-1),",",""))/Lookups!$O$4,0),ROUND(VALUE(LEFT(W33,FIND(" ",W33)-1))*Lookups!$O$3,0)) -> 64 | S33: Jonas | T33: Fischer | U33: 20 mph | V33: 35 mph | W33: 40 miles | X33: 304 Ringstraße, Hamburg, 20095 | Y33: DE | Z33: €800 | AA33: =IF(U33="",INDEX(Lookups!$J$3:$J$5,MATCH(E33,Lookups!$I$3:$I$5,0)),VALUE(LEFT(U33,FIND(" ",U33)-1))) -> 20 | AB33: =VALUE(LEFT(V33,FIND(" ",V33)-1)) -> 35
A34: 33 | B34: =T34&", "&S34 -> Fischer, Jonas | C34: March | D34: ="Q"&ROUNDUP(MATCH(C34,Lookups!$L$3:$L$14,0)/3,0) -> Q1 | E34: Electric Skateboard | F34: 305 Ringstraße | G34: Hamburg | H34: 20095 | I34: =INDEX(Lookups!$B$3:$B$6,MATCH(Y34,Lookups!$A$3:$A$6,0)) -> Germany | J34: =INDEX(Lookups!$C$3:$C$6,MATCH(Y34,Lookups!$A$3:$A$6,0)) -> Europe | K34: =INDEX(Lookups!$D$3:$D$6,MATCH(Y34,Lookups!$A$3:$A$6,0)) -> EUR | L34: 950 | M34: =ROUND(L34*INDEX(Lookups!$G$3:$G$5,MATCH(K34,Lookups!$F$3:$F$5,0)),0) -> 1026 | N34: 160 | O34: 0 | P34: =ROUND(N34*M34*(1-O34/100),0) -> 164160 | Q34: =ROUND(AA34*Lookups!$O$3,0)&" - "&ROUND(AB34*Lookups!$O$3,0)&" km/h" -> 29 - 45 km/h | R34: =IF(ISNUMBER(SEARCH("meters",W34)),ROUND(VALUE(SUBSTITUTE(LEFT(W34,FIND(" ",W34)-1),",",""))/Lookups!$O$4,0),ROUND(VALUE(LEFT(W34,FIND(" ",W34)-1))*Lookups!$O$3,0)) -> 40 | S34: Jonas | T34: Fischer | U34: 18 mph | V34: 28 mph | W34: 25 miles | X34: 305 Ringstraße, Hamburg, 20095 | Y34: DE | Z34: €950 | AA34: =IF(U34="",INDEX(Lookups!$J$3:$J$5,MATCH(E34,Lookups!$I$3:$I$5,0)),VALUE(LEFT(U34,FIND(" ",U34)-1))) -> 18 | AB34: =VALUE(LEFT(V34,FIND(" ",V34)-1)) -> 28
A35: 34 | B35: =T35&", "&S35 -> Bernard, Théo | C35: March | D35: ="Q"&ROUNDUP(MATCH(C35,Lookups!$L$3:$L$14,0)/3,0) -> Q1 | E35: Electric Unicycle | F35: 56 Boulevard Saint-Germain | G35: Paris | H35: 75005 | I35: =INDEX(Lookups!$B$3:$B$6,MATCH(Y35,Lookups!$A$3:$A$6,0)) -> France | J35: =INDEX(Lookups!$C$3:$C$6,MATCH(Y35,Lookups!$A$3:$A$6,0)) -> Europe | K35: =INDEX(Lookups!$D$3:$D$6,MATCH(Y35,Lookups!$A$3:$A$6,0)) -> EUR | L35: 1100 | M35: =ROUND(L35*INDEX(Lookups!$G$3:$G$5,MATCH(K35,Lookups!$F$3:$F$5,0)),0) -> 1188 | N35: 110 | O35: 0 | P35: =ROUND(N35*M35*(1-O35/100),0) -> 130680 | Q35: =ROUND(AA35*Lookups!$O$3,0)&" - "&ROUND(AB35*Lookups!$O$3,0)&" km/h" -> 24 - 48 km/h | R35: =IF(ISNUMBER(SEARCH("meters",W35)),ROUND(VALUE(SUBSTITUTE(LEFT(W35,FIND(" ",W35)-1),",",""))/Lookups!$O$4,0),ROUND(VALUE(LEFT(W35,FIND(" ",W35)-1))*Lookups!$O$3,0)) -> 48 | S35: Théo | T35: Bernard | U35: 15 mph | V35: 30 mph | W35: 48,280 meters | X35: 56 Boulevard Saint-Germain, Paris, 75005 | Y35: FR | Z35: €1100 | AA35: =IF(U35="",INDEX(Lookups!$J$3:$J$5,MATCH(E35,Lookups!$I$3:$I$5,0)),VALUE(LEFT(U35,FIND(" ",U35)-1))) -> 15 | AB35: =VALUE(LEFT(V35,FIND(" ",V35)-1)) -> 30
A36: 35 | B36: =T36&", "&S36 -> Bernard, Théo | C36: March | D36: ="Q"&ROUNDUP(MATCH(C36,Lookups!$L$3:$L$14,0)/3,0) -> Q1 | E36: Electric Scooter | F36: 57 Boulevard Saint-Germain | G36: Paris | H36: 75005 | I36: =INDEX(Lookups!$B$3:$B$6,MATCH(Y36,Lookups!$A$3:$A$6,0)) -> France | J36: =INDEX(Lookups!$C$3:$C$6,MATCH(Y36,Lookups!$A$3:$A$6,0)) -> Europe | K36: =INDEX(Lookups!$D$3:$D$6,MATCH(Y36,Lookups!$A$3:$A$6,0)) -> EUR | L36: 900 | M36: =ROUND(L36*INDEX(Lookups!$G$3:$G$5,MATCH(K36,Lookups!$F$3:$F$5,0)),0) -> 972 | N36: 260 | O36: 0 | P36: =ROUND(N36*M36*(1-O36/100),0) -> 252720 | Q36: =ROUND(AA36*Lookups!$O$3,0)&" - "&ROUND(AB36*Lookups!$O$3,0)&" km/h" -> 32 - 56 km/h | R36: =IF(ISNUMBER(SEARCH("meters",W36)),ROUND(VALUE(SUBSTITUTE(LEFT(W36,FIND(" ",W36)-1),",",""))/Lookups!$O$4,0),ROUND(VALUE(LEFT(W36,FIND(" ",W36)-1))*Lookups!$O$3,0)) -> 64 | S36: Théo | T36: Bernard | U36: 20 mph | V36: 35 mph | W36: 40 miles | X36: 57 Boulevard Saint-Germain, Paris, 75005 | Y36: FR | Z36: €900 | AA36: =IF(U36="",INDEX(Lookups!$J$3:$J$5,MATCH(E36,Lookups!$I$3:$I$5,0)),VALUE(LEFT(U36,FIND(" ",U36)-1))) -> 20 | AB36: =VALUE(LEFT(V36,FIND(" ",V36)-1)) -> 35
A37: 36 | B37: =T37&", "&S37 -> Bernard, Théo | C37: March | D37: ="Q"&ROUNDUP(MATCH(C37,Lookups!$L$3:$L$14,0)/3,0) -> Q1 | E37: Electric Skateboard | F37: 58 Boulevard Saint-Germain | G37: Paris | H37: 75005 | I37: =INDEX(Lookups!$B$3:$B$6,MATCH(Y37,Lookups!$A$3:$A$6,0)) -> France | J37: =INDEX(Lookups!$C$3:$C$6,MATCH(Y37,Lookups!$A$3:$A$6,0)) -> Europe | K37: =INDEX(Lookups!$D$3:$D$6,MATCH(Y37,Lookups!$A$3:$A$6,0)) -> EUR | L37: 1050 | M37: =ROUND(L37*INDEX(Lookups!$G$3:$G$5,MATCH(K37,Lookups!$F$3:$F$5,0)),0) -> 1134 | N37: 200 | O37: 0 | P37: =ROUND(N37*M37*(1-O37/100),0) -> 226800 | Q37: =ROUND(AA37*Lookups!$O$3,0)&" - "&ROUND(AB37*Lookups!$O$3,0)&" km/h" -> 29 - 45 km/h | R37: =IF(ISNUMBER(SEARCH("meters",W37)),ROUND(VALUE(SUBSTITUTE(LEFT(W37,FIND(" ",W37)-1),",",""))/Lookups!$O$4,0),ROUND(VALUE(LEFT(W37,FIND(" ",W37)-1))*Lookups!$O$3,0)) -> 40 | S37: Théo | T37: Bernard | U37: 18 mph | V37: 28 mph | W37: 25 miles | X37: 58 Boulevard Saint-Germain, Paris, 75005 | Y37: FR | Z37: €1050 | AA37: =IF(U37="",INDEX(Lookups!$J$3:$J$5,MATCH(E37,Lookups!$I$3:$I$5,0)),VALUE(LEFT(U37,FIND(" ",U37)-1))) -> 18 | AB37: =VALUE(LEFT(V37,FIND(" ",V37)-1)) -> 28
A38: 37 | B38: =T38&", "&S38 -> Joshi, Sanya | C38: April | D38: ="Q"&ROUNDUP(MATCH(C38,Lookups!$L$3:$L$14,0)/3,0) -> Q2 | E38: Electric Unicycle | F38: 456 Brigade Road | G38: Bengaluru | H38: 560001 | I38: =INDEX(Lookups!$B$3:$B$6,MATCH(Y38,Lookups!$A$3:$A$6,0)) -> India | J38: =INDEX(Lookups!$C$3:$C$6,MATCH(Y38,Lookups!$A$3:$A$6,0)) -> Asia | K38: =INDEX(Lookups!$D$3:$D$6,MATCH(Y38,Lookups!$A$3:$A$6,0)) -> INR | L38: 30000 | M38: =ROUND(L38*INDEX(Lookups!$G$3:$G$5,MATCH(K38,Lookups!$F$3:$F$5,0)),0) -> 360 | N38: 200 | O38: 0 | P38: =ROUND(N38*M38*(1-O38/100),0) -> 72000 | Q38: =ROUND(AA38*Lookups!$O$3,0)&" - "&ROUND(AB38*Lookups!$O$3,0)&" km/h" -> 24 - 48 km/h | R38: =IF(ISNUMBER(SEARCH("meters",W38)),ROUND(VALUE(SUBSTITUTE(LEFT(W38,FIND(" ",W38)-1),",",""))/Lookups!$O$4,0),ROUND(VALUE(LEFT(W38,FIND(" ",W38)-1))*Lookups!$O$3,0)) -> 48 | S38: Sanya | T38: Joshi | U38: 15 mph | V38: 30 mph | W38: 30 miles | X38: 456 Brigade Road, Bengaluru, 560001 | Y38: IN | Z38: ₹30,000 | AA38: =IF(U38="",INDEX(Lookups!$J$3:$J$5,MATCH(E38,Lookups!$I$3:$I$5,0)),VALUE(LEFT(U38,FIND(" ",U38)-1))) -> 15 | AB38: =VALUE(LEFT(V38,FIND(" ",V38)-1)) -> 30
A39: 38 | B39: =T39&", "&S39 -> Joshi, Sanya | C39: April | D39: ="Q"&ROUNDUP(MATCH(C39,Lookups!$L$3:$L$14,0)/3,0) -> Q2 | E39: Electric Scooter | F39: 457 Brigade Road | G39: Bengaluru | H39: 560001 | I39: =INDEX(Lookups!$B$3:$B$6,MATCH(Y39,Lookups!$A$3:$A$6,0)) -> India | J39: =INDEX(Lookups!$C$3:$C$6,MATCH(Y39,Lookups!$A$3:$A$6,0)) -> Asia | K39: =INDEX(Lookups!$D$3:$D$6,MATCH(Y39,Lookups!$A$3:$A$6,0)) -> INR | L39: 25000 | M39: =ROUND(L39*INDEX(Lookups!$G$3:$G$5,MATCH(K39,Lookups!$F$3:$F$5,0)),0) -> 300 | N39: 450 | O39: 0 | P39: =ROUND(N39*M39*(1-O39/100),0) -> 135000 | Q39: =ROUND(AA39*Lookups!$O$3,0)&" - "&ROUND(AB39*Lookups!$O$3,0)&" km/h" -> 32 - 56 km/h | R39: =IF(ISNUMBER(SEARCH("meters",W39)),ROUND(VALUE(SUBSTITUTE(LEFT(W39,FIND(" ",W39)-1),",",""))/Lookups!$O$4,0),ROUND(VALUE(LEFT(W39,FIND(" ",W39)-1))*Lookups!$O$3,0)) -> 64 | S39: Sanya | T39: Joshi | U39: 20 mph | V39: 35 mph | W39: 40 miles | X39: 457 Brigade Road, Bengaluru, 560001 | Y39: IN | Z39: ₹25,000 | AA39: =IF(U39="",INDEX(Lookups!$J$3:$J$5,MATCH(E39,Lookups!$I$3:$I$5,0)),VALUE(LEFT(U39,FIND(" ",U39)-1))) -> 20 | AB39: =VALUE(LEFT(V39,FIND(" ",V39)-1)) -> 35
A40: 39 | B40: =T40&", "&S40 -> Joshi, Sanya | C40: April | D40: ="Q"&ROUNDUP(MATCH(C40,Lookups!$L$3:$L$14,0)/3,0) -> Q2 | E40: Electric Skateboard | F40: 458 Brigade Road | G40: Bengaluru | H40: 560001 | I40: =INDEX(Lookups!$B$3:$B$6,MATCH(Y40,Lookups!$A$3:$A$6,0)) -> India | J40: =INDEX(Lookups!$C$3:$C$6,MATCH(Y40,Lookups!$A$3:$A$6,0)) -> Asia | K40: =INDEX(Lookups!$D$3:$D$6,MATCH(Y40,Lookups!$A$3:$A$6,0)) -> INR | L40: 22000 | M40: =ROUND(L40*INDEX(Lookups!$G$3:$G$5,MATCH(K40,Lookups!$F$3:$F$5,0)),0) -> 264 | N40: 300 | O40: 0 | P40: =ROUND(N40*M40*(1-O40/100),0) -> 79200 | Q40: =ROUND(AA40*Lookups!$O$3,0)&" - "&ROUND(AB40*Lookups!$O$3,0)&" km/h" -> 29 - 45 km/h | R40: =IF(ISNUMBER(SEARCH("meters",W40)),ROUND(VALUE(SUBSTITUTE(LEFT(W40,FIND(" ",W40)-1),",",""))/Lookups!$O$4,0),ROUND(VALUE(LEFT(W40,FIND(" ",W40)-1))*Lookups!$O$3,0)) -> 40 | S40: Sanya | T40: Joshi | U40: 18 mph | V40: 28 mph | W40: 25 miles | X40: 458 Brigade Road, Bengaluru, 560001 | Y40: IN | Z40: ₹22,000 | AA40: =IF(U40="",INDEX(Lookups!$J$3:$J$5,MATCH(E40,Lookups!$I$3:$I$5,0)),VALUE(LEFT(U40,FIND(" ",U40)-1))) -> 18 | AB40: =VALUE(LEFT(V40,FIND(" ",V40)-1)) -> 28
...

Sheet Original Data
A1: Sales Rep ID | B1: Rep First Name | C1: Rep Last Name | D1: Month | E1: Product Type | F1: Min Speed | G1: Speed | H1: Distance | I1: Shipping Address | J1: Country Code | K1: Unit Price | L1: Units Sold | M1: Discount (%)
A2: 1 | B2: Sanya | C2: Joshi | D2: January | E2: Electric Unicycle | F2: 15 mph | G2: 30 mph | H2: 30 miles | I2: 456 Brigade Road, Bengaluru, 560001 | J2: IN | K2: ₹30,000 | L2: 150 | M2: 10
A3: 2 | B3: Sanya | C3: Joshi | D3: January | E3: Electric Scooter | F3: 20 mph | G3: 35 mph | H3: 40 miles | I3: 457 Brigade Road, Bengaluru, 560001 | J3: IN | K3: ₹25,000 | L3: 300 | M3: 10
A4: 2 | B4: Sanya | C4: Joshi | D4: January | E4: Electric Scooter | F4: 20 mph | G4: 35 mph | H4: 40 miles | I4: 457 Brigade Road, Bengaluru, 560001 | J4: IN | K4: ₹25,000 | L4: 300 | M4: 10
A5: 3 | B5: Sanya | C5: Joshi | D5: January | E5: Electric Skateboard | F5: 18 mph | G5: 28 mph | H5: 25 miles | I5: 458 Brigade Road, Bengaluru, 560001 | J5: IN | K5: ₹22,000 | L5: 200 | M5: 10
A6: 4 | B6: Fang | C6: Liu | D6: January | E6: Electric Unicycle | F6: 15 mph | G6: 30 mph | H6: 30 miles | I6: 99 Nanjing Road, Shanghai, 200001 | J6: CN | K6: ¥5,000 | L6: 500 | M6: 10
A7: 5 | B7: Fang | C7: Liu | D7: January | E7: Electric Scooter | F7: 20 mph | G7: 35 mph | H7: 40 miles | I7: 100 Nanjing Road, Shanghai, 200001 | J7: CN | K7: ¥3,500 | L7: 1000 | M7: 10
A8: 6 | B8: Fang | C8: Liu | D8: January | E8: Electric Skateboard | G8: 28 mph | H8: 40,230 meters | I8: 101 Nanjing Road, Shanghai, 200001 | J8: CN | K8: ¥4,200 | L8: 800 | M8: 10
A9: 7 | B9: Jonas | C9: Fischer | D9: January | E9: Electric Unicycle | F9: 15 mph | G9: 30 mph | H9: 48,280 meters | I9: 303 Ringstraße, Hamburg, 20095 | J9: DE | K9: €1000 | L9: 120 | M9: 10
A10: 8 | B10: Jonas | C10: Fischer | D10: January | E10: Electric Scooter | F10: 20 mph | G10: 35 mph | H10: 40 miles | I10: 304 Ringstraße, Hamburg, 20095 | J10: DE | K10: €800 | L10: 200 | M10: 10
A11: 8 | B11: Jonas | C11: Fischer | D11: January | E11: Electric Scooter | F11: 20 mph | G11: 35 mph | H11: 40 miles | I11: 304 Ringstraße, Hamburg, 20095 | J11: DE | K11: €800 | L11: 200 | M11: 10
A12: 9 | B12: Jonas | C12: Fischer | D12: January | E12: Electric Skateboard | F12: 18 mph | G12: 28 mph | H12: 25 miles | I12: 305 Ringstraße, Hamburg, 20095 | J12: DE | K12: €950 | L12: 150 | M12: 10
A13: 10 | B13: Théo | C13: Bernard | D13: January | E13: Electric Unicycle | F13: 15 mph | G13: 30 mph | H13: 30 miles | I13: 56 Boulevard Saint-Germain, Paris, 75005 | J13: FR | K13: €1100 | L13: 100 | M13: 10
A14: 11 | B14: Théo | C14: Bernard | D14: January | E14: Electric Scooter | F14: 20 mph | G14: 35 mph | H14: 64,370 meters | I14: 57 Boulevard Saint-Germain, Paris, 75005 | J14: FR | K14: €900 | L14: 250 | M14: 10
A15: 12 | B15: Théo | C15: Bernard | D15: January | E15: Electric Skateboard | F15: 18 mph | G15: 28 mph | H15: 25 miles | I15: 58 Boulevard Saint-Germain, Paris, 75005 | J15: FR | K15: €1050 | L15: 180 | M15: 10
A16: 13 | B16: Sanya | C16: Joshi | D16: February | E16: Electric Unicycle | F16: 15 mph | G16: 30 mph | H16: 30 miles | I16: 456 Brigade Road, Bengaluru, 560001 | J16: IN | K16: ₹30,000 | L16: 160 | M16: 0
A17: 14 | B17: Sanya | C17: Joshi | D17: February | E17: Electric Scooter | G17: 35 mph | H17: 40 miles | I17: 457 Brigade Road, Bengaluru, 560001 | J17: IN | K17: ₹25,000 | L17: 350 | M17: 0
A18: 15 | B18: Sanya | C18: Joshi | D18: February | E18: Electric Skateboard | F18: 18 mph | G18: 28 mph | H18: 25 miles | I18: 458 Brigade Road, Bengaluru, 560001 | J18: IN | K18: ₹22,000 | L18: 220 | M18: 0
A19: 16 | B19: Fang | C19: Liu | D19: February | E19: Electric Unicycle | F19: 15 mph | G19: 30 mph | H19: 48,280 meters | I19: 99 Nanjing Road, Shanghai, 200001 | J19: CN | K19: ¥5,000 | L19: 550 | M19: 0
A20: 17 | B20: Fang | C20: Liu | D20: February | E20: Electric Scooter | F20: 20 mph | G20: 35 mph | H20: 40 miles | I20: 100 Nanjing Road, Shanghai, 200001 | J20: CN | K20: ¥3,500 | L20: 1200 | M20: 0
A21: 17 | B21: Fang | C21: Liu | D21: February | E21: Electric Scooter | F21: 20 mph | G21: 35 mph | H21: 40 miles | I21: 100 Nanjing Road, Shanghai, 200001 | J21: CN | K21: ¥3,500 | L21: 1200 | M21: 0
A22: 18 | B22: Fang | C22: Liu | D22: February | E22: Electric Skateboard | F22: 18 mph | G22: 28 mph | H22: 25 miles | I22: 101 Nanjing Road, Shanghai, 200001 | J22: CN | K22: ¥4,200 | L22: 850 | M22: 0
A23: 19 | B23: Jonas | C23: Fischer | D23: February | E23: Electric Unicycle | F23: 15 mph | G23: 30 mph | H23: 30 miles | I23: 303 Ringstraße, Hamburg, 20095 | J23: DE | K23: €1000 | L23: 130 | M23: 0
A24: 20 | B24: Jonas | C24: Fischer | D24: February | E24: Electric Scooter | F24: 20 mph | G24: 35 mph | H24: 40 miles | I24: 304 Ringstraße, Hamburg, 20095 | J24: DE | K24: €800 | L24: 220 | M24: 0
A25: 21 | B25: Jonas | C25: Fischer | D25: February | E25: Electric Skateboard | F25: 18 mph | G25: 28 mph | H25: 25 miles | I25: 305 Ringstraße, Hamburg, 20095 | J25: DE | K25: €950 | L25: 160 | M25: 0
A26: 22 | B26: Théo | C26: Bernard | D26: February | E26: Electric Unicycle | F26: 15 mph | G26: 30 mph | H26: 30 miles | I26: 56 Boulevard Saint-Germain, Paris, 75005 | J26: FR | K26: €1100 | L26: 110 | M26: 0
A27: 23 | B27: Théo | C27: Bernard | D27: February | E27: Electric Scooter | F27: 20 mph | G27: 35 mph | H27: 40 miles | I27: 57 Boulevard Saint-Germain, Paris, 75005 | J27: FR | K27: €900 | L27: 260 | M27: 0
A28: 23 | B28: Théo | C28: Bernard | D28: February | E28: Electric Scooter | F28: 20 mph | G28: 35 mph | H28: 40 miles | I28: 57 Boulevard Saint-Germain, Paris, 75005 | J28: FR | K28: €900 | L28: 260 | M28: 0
A29: 24 | B29: Théo | C29: Bernard | D29: February | E29: Electric Skateboard | F29: 18 mph | G29: 28 mph | H29: 40,230 meters | I29: 58 Boulevard Saint-Germain, Paris, 75005 | J29: FR | K29: €1050 | L29: 200 | M29: 0
A30: 25 | B30: Sanya | C30: Joshi | D30: March | E30: Electric Unicycle | F30: 15 mph | G30: 30 mph | H30: 30 miles | I30: 456 Brigade Road, Bengaluru, 560001 | J30: IN | K30: ₹30,000 | L30: 160 | M30: 0
A31: 26 | B31: Sanya | C31: Joshi | D31: March | E31: Electric Scooter | G31: 35 mph | H31: 40 miles | I31: 457 Brigade Road, Bengaluru, 560001 | J31: IN | K31: ₹25,000 | L31: 350 | M31: 0
A32: 27 | B32: Sanya | C32: Joshi | D32: March | E32: Electric Skateboard | F32: 18 mph | G32: 28 mph | H32: 25 miles | I32: 458 Brigade Road, Bengaluru, 560001 | J32: IN | K32: ₹22,000 | L32: 220 | M32: 0
A33: 28 | B33: Fang | C33: Liu | D33: March | E33: Electric Unicycle | F33: 15 mph | G33: 30 mph | H33: 30 miles | I33: 99 Nanjing Road, Shanghai, 200001 | J33: CN | K33: ¥5,000 | L33: 550 | M33: 0
A34: 29 | B34: Fang | C34: Liu | D34: March | E34: Electric Scooter | F34: 20 mph | G34: 35 mph | H34: 64,370 meters | I34: 100 Nanjing Road, Shanghai, 200001 | J34: CN | K34: ¥3,500 | L34: 1200 | M34: 0
A35: 30 | B35: Fang | C35: Liu | D35: March | E35: Electric Skateboard | F35: 18 mph | G35: 28 mph | H35: 25 miles | I35: 101 Nanjing Road, Shanghai, 200001 | J35: CN | K35: ¥4,200 | L35: 850 | M35: 0
A36: 30 | B36: Fang | C36: Liu | D36: March | E36: Electric Skateboard | F36: 18 mph | G36: 28 mph | H36: 25 miles | I36: 101 Nanjing Road, Shanghai, 200001 | J36: CN | K36: ¥4,200 | L36: 850 | M36: 0
